Workbook

Sheet Ats Slide
A1: DELTA COST CENTRE MODEL - DRAFT&CONFIDENTIAL | Y1: STATUS | AI1: 1000000
B2: - Expect cash usage of $3m-$3.5m upon signing | Y2: Will Audrey be on the call later? | Z2: CHANGE TO MILLIONS
B3: - Delta is expected to add approx $3.8m to opex run - rate ($2.8m of which are headcount costs)
B4: - Includes 14 existing heads and 14 new hires (13 engineers plus 1 product designer)
B5: - cost centre will roll into Jon Oakes
B6: - 1-time integration/deal costs of $900k, additional costs of $452k expected to be negotiated as part of purchase price/working capital negotiation
B7: - Founder earnout of $2.25 is not included in the p&l
E9: 2019E | H9: 2020E | M9: 2021 | R9: 2022 | W9: TOTAL COSTS
C10: Provided by | E10: Q319 | F10: Q419 | G10: 2H19 | H10: 1Q20 | I10: 2Q20 | J10: 3Q20 | K10: 4Q20 | L10: FY2020 | M10: Q1 | N10: Q2 | O10: Q3 | P10: Q4 | Q10: FY | R10: Q1 | S10: Q2 | T10: Q3 | U10: Q4 | V10: FY | W10: FY 2019 - 2022
B11: Headcount (HC):
B12: Delta Employees | F12: =[1]Sheet1!$A$28 -> 14 | G12: =F12 -> 14 | H12: =G12 -> 14 | I12: =H12 -> 14 | J12: =I12 -> 14 | K12: =J12 -> 14 | L12: =K12 -> 14 | M12: =L12 -> 14 | N12: =M12 -> 14 | ... W12: =V12 -> 14
B13: New Asia Hires | F13: 6 | G13: =F13 -> 6 | H13: 12 | I13: 12 | J13: 14 | K13: 14 | L13: =K13 -> 14 | M13: 14 | N13: 14 | O13: 14 | P13: 14 | Q13: =P13 -> 14 | R13: =P13 -> 14 | S13: =R13 -> 14 | T13: =S13 -> 14 | U13: =T13 -> 14 | V13: =U13 -> 14 | W13: =V13 -> 14 | Y13: 1.5m founder holdback, 25%, 25% and 50% - 375k in q4 2020 - new category
B14: Total Ending HC | F14: =F12+F13 -> 20 | G14: =G12+G13 -> 20 | H14: =H12+H13 -> 26 | I14: =I12+I13 -> 26 | J14: =J12+J13 -> 28 | K14: =K12+K13 -> 28 | L14: =L12+L13 -> 28 | M14: =M12+M13 -> 28 | ... V14: =V12+V13 -> 28 | W14: =V14 -> 28
B16: Run Rate Costs:
B17: =B12 -> Delta Employees | F17: =F43 -> 311675.06 | G17: =G43 -> 311675.06 | H17: =H43 -> 311675.06 | I17: =I43 -> 311675.06 | J17: =J43 -> 311675.06 | K17: =K43 -> 311675.06 | L17: =L43 -> 1246699.8 | M17: =M43 -> 326196.36 | ... W17: =W43 -> 4122683.7
B18: =B13 -> New Asia Hires | F18: =F69 -> 240224.75 | G18: =G69 -> 240224.65 | H18: =H69 -> 397541.73 | I18: =I69 -> 314634.23 | J18: =J69 -> 394709.05 | K18: =K69 -> 367073.22 | L18: =L69 -> 1473957.4 | M18: =M69 -> 385426.87 | ... W18: =W69 -> 4874680.6 | Z18: More engineers | AA18: =(L18-L17)/L17 -> 0.18228734
B19: Total HC Costs | F19: =F43+F69 -> 551899.81 | G19: =G43+G69 -> 551899.71 | H19: =H43+H69 -> 709216.79 | I19: =I43+I69 -> 626309.29 | J19: =J43+J69 -> 706384.11 | K19: =K43+K69 -> 678748.28 | L19: =L43+L69 -> 2720657.2 | M19: =M43+M69 -> 711623.23 | ... W19: =W43+W69 -> 8997364.3 | Z19: =L17+L18 -> 2720657.2
B20: T&E | F20: =F85 -> 17500 | G20: =G85 -> 17500 | H20: =H85 -> 32500 | I20: =I85 -> 32500 | J20: =J85 -> 35000 | K20: =K85 -> 35000 | L20: =L85 -> 135000 | M20: =#REF!+M3 -> #REF! | N20: =#REF!+N3 -> #REF! | O20: =#REF!+O3 -> #REF! | P20: =#REF!+P3 -> #REF! | Q20: =SUM(M20:P20) -> #REF! | R20: =#REF!+R3 -> #REF! | S20: =#REF!+S3 -> #REF! | T20: =#REF!+T3 -> #REF! | U20: =#REF!+U3 -> #REF! | V20: =SUM(R20:U20) -> #REF! | W20: =G20+L20+Q20+V20 -> #REF!
B21: Facility and Office Exp | F21: =F86 -> 22963 | G21: =G86 -> 22963 | H21: =H86 -> 177439 | I21: =I86 -> 177439 | J21: =J86 -> 154476 | K21: =K86 -> 154476 | L21: =L86 -> 663830 | M21: =#REF!+M4 -> #REF! | N21: =#REF!+N4 -> #REF! | O21: =#REF!+O4 -> #REF! | P21: =#REF!+P4 -> #REF! | Q21: =SUM(M21:P21) -> #REF! | R21: =#REF!+R4 -> #REF! | S21: =#REF!+S4 -> #REF! | T21: =#REF!+T4 -> #REF! | U21: =#REF!+U4 -> #REF! | V21: =SUM(R21:U21) -> #REF! | W21: =G21+L21+Q21+V21 -> #REF!
B22: IT Costs - wi fi&special software | C22: Bill Bragg | F22: =F90 -> 20000 | G22: =G90 -> 20000 | H22: =H90 -> 10000 | I22: =I90 -> 10000 | J22: =J90 -> 20000 | K22: =K90 -> 10000 | L22: =L90 -> 50000 | M22: =K22 -> 10000 | N22: =M22 -> 10000 | O22: =N22 -> 10000 | P22: =M22 -> 10000 | Q22: =SUM(M22:P22) -> 40000 | R22: =M22 -> 10000 | S22: =R22 -> 10000 | T22: =S22 -> 10000 | U22: =S22 -> 10000 | V22: =SUM(R22:U22) -> 40000 | W22: =G22+L22+Q22+V22 -> 150000
B23: Engineering non h/c | C23: Paul Quinn | F23: =F93 -> 25564.375 | G23: =G93 -> 25564.375 | H23: =H93 -> 19164.375 | I23: =I93 -> 19164.375 | J23: =J93 -> 19414.375 | K23: =K93 -> 6914.375 | L23: =L93 -> 64657.5 | M23: =#REF! -> #REF! | N23: =#REF! -> #REF! | O23: =#REF! -> #REF! | P23: =#REF! -> #REF! | Q23: =SUM(M23:P23) -> #REF! | R23: =#REF! -> #REF! | S23: =#REF! -> #REF! | T23: =#REF! -> #REF! | U23: =#REF! -> #REF! | V23: =SUM(R23:U23) -> #REF! | W23: =#REF! -> #REF!
B24: Tax | C24: Anu/Harvey | F24: =F95 -> 0 | G24: =G95 -> 0 | H24: =H95 -> 0 | I24: =I95 -> 12000 | J24: =J95 -> 0 | K24: =K95 -> 0 | L24: =L95 -> 12000 | M24: =#REF! -> #REF! | N24: =#REF! -> #REF! | O24: =#REF! -> #REF! | P24: =#REF! -> #REF! | Q24: =SUM(M24:P24) -> #REF! | R24: =#REF! -> #REF! | S24: =#REF! -> #REF! | T24: =#REF! -> #REF! | U24: =#REF! -> #REF! | V24: =SUM(R24:U24) -> #REF! | W24: =#REF! -> #REF! | Y24: Stamp duty cost - 2% of shares of company - would it go to p&l?
B25: Other | C25: Nish/Tom | F25: =F96 -> 25000 | G25: =G96 -> 25000 | H25: =H96 -> 25000 | I25: =I96 -> 25000 | J25: =J96 -> 25000 | K25: =K96 -> 25000 | L25: =L96 -> 100000 | M25: =#REF! -> #REF! | N25: =#REF! -> #REF! | O25: =#REF! -> #REF! | P25: =#REF! -> #REF! | Q25: =SUM(M25:P25) -> #REF! | R25: =#REF! -> #REF! | S25: =#REF! -> #REF! | T25: =#REF! -> #REF! | U25: =#REF! -> #REF! | V25: =SUM(R25:U25) -> #REF! | W25: =#REF! -> #REF!
B26: Non-HC Costs | F26: =F98-F19-F112 -> 111027.23 | G26: =G98-G19-G112 -> 111027.23 | H26: =H98-H19-H112 -> 264103.23 | I26: =I98-I19-I112 -> 276103.23 | J26: =J98-J19-J112 -> 253890.22 | K26: 231390.5 | L26: =SUM(H26:K26) -> 1025487.2 | M26: =M98-M19-M112 -> 227975.8 | N26: =N98-N19-N112 -> 239975.85 | O26: =O98-O19-O112 -> 227975.85 | P26: =P98-P19-P112 -> 227975.85 | Q26: =Q98-Q19-Q112 -> 923903.85 | R26: =R98-R19-R112 -> 227975.8 | S26: =S98-S19-S112 -> 239975.85 | T26: =T98-T19-T112 -> 227975.85 | ... W26: =W98-W19-W112 -> 2984322.3 | Z26: =SUM(H26:K26) -> 1025487.2
B27: Total Run Rate Costs | F27: =F19+F26 -> 662927.03 | G27: =G19+G26 -> 662926.93 | H27: =H19+H26 -> 973320.01 | I27: =I19+I26 -> 902412.51 | J27: =J19+J26 -> 960274.34 | K27: =K19+K26 -> 910138.78 | L27: =L19+L26 -> 3746144.3 | M27: =M19+M26 -> 939599.03 | ... W27: =W19+W26 -> 11981687
B29: Cost of goods sold
B30: Inventory write off - DokiPal units that we will not sell | C30: Audrey | F30: =100000 -> 100000 | G30: =SUM(E30:F30) -> 100000 | W30: =G30+L30+Q30+V30 -> 100000
B31: Inventory write off - Buy back of DokiPal units | F31: ='Recoverable units'!F20 -> 164003.4 | G31: =SUM(E31:F31) -> 164003.4 | W31: =G31+L31+Q31+V31 -> 164003.4
B33: Operating costs:
B35: Gross wages - yoy inc | H35: 0 | M35: 0.05 | R35: =M35 -> 0.05
B36: Gross Wages | C36: HR | F36: =[1]Sheet1!$G$30/4 -> 224588.32 | G36: =SUM(E36:F36) -> 224588.32 | H36: =F36*(1+H35) -> 224588.32 | I36: =H36 -> 224588.32 | J36: =I36 -> 224588.32 | K36: =J36 -> 224588.32 | L36: =SUM(H36:K36) -> 898353.3 | M36: =H36*(1+M35) -> 235817.74 | N36: =M36 -> 235817.74 | O36: =N36 -> 235817.74 | P36: =O36 -> 235817.74 | Q36: =SUM(M36:P36) -> 943270.96 | R36: =M36*(1+R35) -> 247608.63 | S36: =R36 -> 247608.63 | T36: =S36 -> 247608.63 | U36: =T36 -> 247608.63 | V36: =SUM(R36:U36) -> 990434.51 | W36: =G36+L36+Q36+V36 -> 3056647.1
B37: Bonus - yoy inc | H37: 0 | M37: 0.05 | R37: =M37 -> 0.05 | W37: =G37+L37+Q37+V37 -> 0
B38: Bonus | C38: HR | F38: =[1]Sheet1!$K$32/4 -> 27955.076 | G38: =SUM(E38:F38) -> 27955.076 | H38: =F38*(1+H37) -> 27955.076 | I38: =H38 -> 27955.076 | J38: =I38 -> 27955.076 | K38: =J38 -> 27955.076 | L38: =SUM(H38:K38) -> 111820.3 | M38: =H38*(1+M37) -> 29352.83 | N38: =M38 -> 29352.83 | O38: =N38 -> 29352.83 | P38: =O38 -> 29352.83 | Q38: =SUM(M38:P38) -> 117411.32 | R38: =M38*(1+R37) -> 30820.471 | S38: =R38 -> 30820.471 | T38: =S38 -> 30820.471 | U38: =T38 -> 30820.471 | V38: =SUM(R38:U38) -> 123281.88 | W38: =G38+L38+Q38+V38 -> 380468.58
B39: Fringe assumption | F39: 0.15 | G39: =F39 -> 0.15 | H39: =G39 -> 0.15 | I39: =H39 -> 0.15 | J39: =I39 -> 0.15 | K39: =J39 -> 0.15 | L39: =K39 -> 0.15 | M39: =L39 -> 0.15 | N39: =M39 -> 0.15 | ... V39: =U39 -> 0.15 | W39: =G39+L39+Q39+V39 -> 0.6
B40: Fringe | C40: HR | F40: =SUM(F36:F38)*$F$39 -> 37881.51 | G40: =SUM(E40:F40) -> 37881.51 | H40: =SUM(H36:H38)*$F$39 -> 37881.51 | I40: =SUM(I36:I38)*$F$39 -> 37881.51 | J40: =SUM(J36:J38)*$F$39 -> 37881.51 | K40: =SUM(K36:K38)*$F$39 -> 37881.51 | L40: =SUM(H40:K40) -> 151526.04 | M40: =SUM(M36:M38)*$F$39 -> 39775.593 | N40: =M40 -> 39775.593 | O40: =N40 -> 39775.593 | P40: =O40 -> 39775.593 | Q40: =SUM(M40:P40) -> 159102.37 | R40: =SUM(R36:R38)*$F$39 -> 41764.372 | S40: =SUM(S36:S38)*$F$39 -> 41764.365 | T40: =SUM(T36:T38)*$F$39 -> 41764.365 | U40: =SUM(U36:U38)*$F$39 -> 41764.365 | V40: =SUM(R40:U40) -> 167057.47 | W40: =G40+L40+Q40+V40 -> 515567.39
B41: Retention | C41: HR | F41: =((85000/18)*3)+(85000/36)*3 -> 21250 | G41: =SUM(E41:F41) -> 21250 | H41: =F41 -> 21250 | I41: =H41 -> 21250 | J41: =I41 -> 21250 | K41: =J41 -> 21250 | L41: =SUM(H41:K41) -> 85000 | M41: =K41 -> 21250 | N41: =(85000/36)*3 -> 7083.3333 | O41: =N41 -> 7083.3333 | P41: =O41 -> 7083.3333 | Q41: =SUM(M41:P41) -> 42500 | R41: =N41 -> 7083.3333 | S41: =R41 -> 7083.3333 | T41: =S41 -> 7083.3333 | V41: =SUM(R41:U41) -> 21250 | W41: =G41+L41+Q41+V41 -> 170000
B42: Severance | C42: HR | F42: 0 | G42: =SUM(E42:F42) -> 0 | H42: 0 | I42: 0 | J42: 0 | K42: 0 | L42: =SUM(H42:K42) -> 0 | M42: 0 | N42: =M42 -> 0 | O42: =N42 -> 0 | P42: =O42 -> 0 | Q42: =SUM(M42:P42) -> 0 | R42: 0 | S42: 0 | T42: 0 | U42: 0 | V42: =SUM(R42:U42) -> 0 | W42: =G42+L42+Q42+V42 -> 0
B43: HC Related costs | C43: HR | F43: =SUM(F36:F42) -> 311675.06 | G43: =SUM(E43:F43) -> 311675.06 | H43: =SUM(H36:H42) -> 311675.06 | I43: =SUM(I36:I42) -> 311675.06 | J43: =SUM(J36:J42) -> 311675.06 | K43: =SUM(K36:K42) -> 311675.06 | L43: =SUM(L36:L42) -> 1246699.8 | M43: =SUM(M36:M42) -> 326196.36 | N43: =SUM(N36:N42) -> 312029.65 | O43: =SUM(O36:O42) -> 312029.65 | ... V43: =SUM(V36:V42) -> 1302024 | W43: =G43+L43+Q43+V43 -> 4122683.7 | AI43: HC Costs Copy of Delta Comp v2- 9.27.19 - Sent to Casper.xlsx
B44: T&E - per person p.a | F44: =5000/4 -> 1250 | G44: =SUM(E44:F44) -> 1250 | H44: =F44 -> 1250 | I44: =H44 -> 1250 | J44: =I44 -> 1250 | K44: =J44 -> 1250 | L44: =SUM(H44:K44) -> 5000 | M44: =H44 -> 1250 | N44: =I44 -> 1250 | O44: =J44 -> 1250 | P44: =K44 -> 1250 | Q44: =SUM(M44:P44) -> 5000 | R44: =M44 -> 1250 | S44: =N44 -> 1250 | T44: =O44 -> 1250 | U44: =P44 -> 1250 | V44: =SUM(R44:U44) -> 5000 | W44: =G44+L44+Q44+V44 -> 16250
B45: T&E | C45: FP&A | F45: =F12*$F44 -> 17500 | G45: =SUM(E45:F45) -> 17500 | H45: =H12*$F44 -> 17500 | I45: =I12*$F44 -> 17500 | J45: =J12*$F44 -> 17500 | K45: =K12*$F44 -> 17500 | L45: =SUM(H45:K45) -> 70000 | M45: =M12*$F44 -> 17500 | N45: =N12*$F44 -> 17500 | O45: =O12*$F44 -> 17500 | P45: =P12*$F44 -> 17500 | Q45: =SUM(M45:P45) -> 70000 | R45: =R12*$F44 -> 17500 | S45: =S12*$F44 -> 17500 | T45: =T12*$F44 -> 17500 | U45: =U12*$F44 -> 17500 | V45: =SUM(R45:U45) -> 70000 | W45: =G45+L45+Q45+V45 -> 227500
...

Sheet Financial model
A1: DELTA COST CENTRE MODEL - DRAFT&CONFIDENTIAL | Y1: STATUS
B2: - Expect cash usage of $3m-$3.5m upon signing | Y2: Will Audrey be on the call later?
B3: - Delta is expected to add approx $3.8m to opex run - rate ($2.8m of which are headcount costs)
B4: - Includes 14 existing heads and 14 new hires (13 engineers plus 1 product designer)
B5: - cost centre will roll into Jon Oakes
B6: - 1-time integration/deal costs of $900k, additional costs of $452k expected to be negotiated as part of purchase price/working capital negotiation
B7: - Founder earnout of $2.25 is not included in the p&l
E9: 2019 | H9: 2020 | M9: 2021 | R9: 2022 | W9: TOTAL COSTS
C10: Provided by | E10: Q3 | F10: Q4 | G10: FY | H10: Q1 | I10: Q2 | J10: Q3 | K10: Q4 | L10: FY | M10: Q1 | N10: Q2 | O10: Q3 | P10: Q4 | Q10: FY | R10: Q1 | S10: Q2 | T10: Q3 | U10: Q4 | V10: FY | W10: FY 2019 - 2022
B11: Delta Employees | F11: =[1]Sheet1!$A$28 -> 14 | G11: =F11 -> 14 | H11: =G11 -> 14 | I11: =H11 -> 14 | J11: =I11 -> 14 | K11: =J11 -> 14 | L11: =K11 -> 14 | M11: =L11 -> 14 | N11: =M11 -> 14 | ... W11: =V11 -> 14
B12: New Employees in HK | F12: 6 | G12: =F12 -> 6 | H12: 12 | I12: 12 | J12: 14 | K12: 14 | L12: =K12 -> 14 | M12: 14 | N12: 14 | O12: 14 | P12: 14 | Q12: =P12 -> 14 | R12: =P12 -> 14 | S12: =R12 -> 14 | T12: =S12 -> 14 | U12: =T12 -> 14 | V12: =U12 -> 14 | W12: =V12 -> 14
B13: TOTAL DELTA HC | F13: =F11+F12 -> 20 | G13: =G11+G12 -> 20 | H13: =H11+H12 -> 26 | I13: =I11+I12 -> 26 | J13: =J11+J12 -> 28 | K13: =K11+K12 -> 28 | L13: =L11+L12 -> 28 | M13: =M11+M12 -> 28 | ... V13: =V11+V12 -> 28 | W13: =V13 -> 28
B15: Cost of goods sold
B16: Inventory write off - DokiPal units that we will not sell | C16: Audrey | F16: =100000 -> 100000 | G16: =SUM(E16:F16) -> 100000 | W16: =G16+L16+Q16+V16 -> 100000
B17: Inventory write off - Buy back of DokiPal units | F17: ='Recoverable units'!F20 -> 164003.4 | G17: =SUM(E17:F17) -> 164003.4 | W17: =G17+L17+Q17+V17 -> 164003.4
B19: Operating costs:
B21: Gross wages - yoy inc | H21: 0 | M21: 0.05 | R21: =M21 -> 0.05
B22: Gross Wages | C22: HR | F22: =[1]Sheet1!$G$30/4 -> 224588.32 | G22: =SUM(E22:F22) -> 224588.32 | H22: =F22*(1+H21) -> 224588.32 | I22: =H22 -> 224588.32 | J22: =I22 -> 224588.32 | K22: =J22 -> 224588.32 | L22: =SUM(H22:K22) -> 898353.3 | M22: =H22*(1+M21) -> 235817.74 | N22: =M22 -> 235817.74 | O22: =N22 -> 235817.74 | P22: =O22 -> 235817.74 | Q22: =SUM(M22:P22) -> 943270.96 | R22: =M22*(1+R21) -> 247608.63 | S22: =R22 -> 247608.63 | T22: =S22 -> 247608.63 | U22: =T22 -> 247608.63 | V22: =SUM(R22:U22) -> 990434.51 | W22: =G22+L22+Q22+V22 -> 3056647.1
B23: Bonus - yoy inc | H23: 0 | M23: 0.05 | R23: =M23 -> 0.05 | W23: =G23+L23+Q23+V23 -> 0
B24: Bonus | C24: HR | F24: =[1]Sheet1!$K$32/4 -> 27955.076 | G24: =SUM(E24:F24) -> 27955.076 | H24: =F24*(1+H23) -> 27955.076 | I24: =H24 -> 27955.076 | J24: =I24 -> 27955.076 | K24: =J24 -> 27955.076 | L24: =SUM(H24:K24) -> 111820.3 | M24: =H24*(1+M23) -> 29352.83 | N24: =M24 -> 29352.83 | O24: =N24 -> 29352.83 | P24: =O24 -> 29352.83 | Q24: =SUM(M24:P24) -> 117411.32 | R24: =M24*(1+R23) -> 30820.471 | S24: =R24 -> 30820.471 | T24: =S24 -> 30820.471 | U24: =T24 -> 30820.471 | V24: =SUM(R24:U24) -> 123281.88 | W24: =G24+L24+Q24+V24 -> 380468.58
B25: Fringe assumption | F25: 0.15 | G25: =F25 -> 0.15 | H25: =G25 -> 0.15 | I25: =H25 -> 0.15 | J25: =I25 -> 0.15 | K25: =J25 -> 0.15 | L25: =K25 -> 0.15 | M25: =L25 -> 0.15 | N25: =M25 -> 0.15 | ... V25: =U25 -> 0.15 | W25: =G25+L25+Q25+V25 -> 0.6
B26: Fringe | C26: HR | F26: =SUM(F22:F24)*$F$25 -> 37881.51 | G26: =SUM(E26:F26) -> 37881.51 | H26: =SUM(H22:H24)*$F$25 -> 37881.51 | I26: =SUM(I22:I24)*$F$25 -> 37881.51 | J26: =SUM(J22:J24)*$F$25 -> 37881.51 | K26: =SUM(K22:K24)*$F$25 -> 37881.51 | L26: =SUM(H26:K26) -> 151526.04 | M26: =SUM(M22:M24)*$F$25 -> 39775.593 | N26: =M26 -> 39775.593 | O26: =N26 -> 39775.593 | P26: =O26 -> 39775.593 | Q26: =SUM(M26:P26) -> 159102.37 | R26: =SUM(R22:R24)*$F$25 -> 41764.372 | S26: =SUM(S22:S24)*$F$25 -> 41764.365 | T26: =SUM(T22:T24)*$F$25 -> 41764.365 | U26: =SUM(U22:U24)*$F$25 -> 41764.365 | V26: =SUM(R26:U26) -> 167057.47 | W26: =G26+L26+Q26+V26 -> 515567.39
B27: Retention | C27: HR | F27: =((85000/18)*3)+(85000/36)*3 -> 21250 | G27: =SUM(E27:F27) -> 21250 | H27: =F27 -> 21250 | I27: =H27 -> 21250 | J27: =I27 -> 21250 | K27: =J27 -> 21250 | L27: =SUM(H27:K27) -> 85000 | M27: =K27 -> 21250 | N27: =(85000/36)*3 -> 7083.3333 | O27: =N27 -> 7083.3333 | P27: =O27 -> 7083.3333 | Q27: =SUM(M27:P27) -> 42500 | R27: =N27 -> 7083.3333 | S27: =R27 -> 7083.3333 | T27: =S27 -> 7083.3333 | V27: =SUM(R27:U27) -> 21250 | W27: =G27+L27+Q27+V27 -> 170000
B28: Severance | C28: HR | F28: 0 | G28: =SUM(E28:F28) -> 0 | H28: 0 | I28: 0 | J28: 0 | K28: 0 | L28: =SUM(H28:K28) -> 0 | M28: 0 | N28: =M28 -> 0 | O28: =N28 -> 0 | P28: =O28 -> 0 | Q28: =SUM(M28:P28) -> 0 | R28: 0 | S28: 0 | T28: 0 | U28: 0 | V28: =SUM(R28:U28) -> 0 | W28: =G28+L28+Q28+V28 -> 0
B29: HC Related costs | C29: HR | F29: =SUM(F22:F28) -> 311675.06 | G29: =SUM(E29:F29) -> 311675.06 | H29: =SUM(H22:H28) -> 311675.06 | I29: =SUM(I22:I28) -> 311675.06 | J29: =SUM(J22:J28) -> 311675.06 | K29: =SUM(K22:K28) -> 311675.06 | L29: =SUM(L22:L28) -> 1246699.8 | M29: =SUM(M22:M28) -> 326196.36 | N29: =SUM(N22:N28) -> 312029.65 | O29: =SUM(O22:O28) -> 312029.65 | ... V29: =SUM(V22:V28) -> 1302024 | W29: =G29+L29+Q29+V29 -> 4122683.7 | AI29: HC Costs Copy of Delta Comp v2- 9.27.19 - Sent to Casper.xlsx
B30: T&E - per person p.a | F30: =5000/4 -> 1250 | G30: =SUM(E30:F30) -> 1250 | H30: =F30 -> 1250 | I30: =H30 -> 1250 | J30: =I30 -> 1250 | K30: =J30 -> 1250 | L30: =SUM(H30:K30) -> 5000 | M30: =H30 -> 1250 | N30: =I30 -> 1250 | O30: =J30 -> 1250 | P30: =K30 -> 1250 | Q30: =SUM(M30:P30) -> 5000 | R30: =M30 -> 1250 | S30: =N30 -> 1250 | T30: =O30 -> 1250 | U30: =P30 -> 1250 | V30: =SUM(R30:U30) -> 5000 | W30: =G30+L30+Q30+V30 -> 16250
B31: T&E | C31: FP&A | F31: =F11*$F30 -> 17500 | G31: =SUM(E31:F31) -> 17500 | H31: =H11*$F30 -> 17500 | I31: =I11*$F30 -> 17500 | J31: =J11*$F30 -> 17500 | K31: =K11*$F30 -> 17500 | L31: =SUM(H31:K31) -> 70000 | M31: =M11*$F30 -> 17500 | N31: =N11*$F30 -> 17500 | O31: =O11*$F30 -> 17500 | P31: =P11*$F30 -> 17500 | Q31: =SUM(M31:P31) -> 70000 | R31: =R11*$F30 -> 17500 | S31: =S11*$F30 -> 17500 | T31: =T11*$F30 -> 17500 | U31: =U11*$F30 -> 17500 | V31: =SUM(R31:U31) -> 70000 | W31: =G31+L31+Q31+V31 -> 227500
B32: Facility and Office Exp | C32: Peter | F32: ='8) Facilities'!I41 -> 22963 | G32: =SUM(E32:F32) -> 22963 | H32: ='8) Facilities'!J41/H13*H11 -> 95544.077 | I32: ='8) Facilities'!K41/I13*I11 -> 95544.077 | J32: ='8) Facilities'!L41/J13*J11 -> 77238 | K32: ='8) Facilities'!M41/K13*K11 -> 77238 | L32: =SUM(H32:K32) -> 345564.15 | M32: =K32 -> 77238 | N32: =M32 -> 77238 | O32: =M32 -> 77238 | P32: =N32 -> 77238 | Q32: =SUM(M32:P32) -> 308952 | R32: =P32 -> 77238 | S32: =R32 -> 77238 | T32: =R32 -> 77238 | U32: =S32 -> 77238 | V32: =SUM(R32:U32) -> 308952 | W32: =G32+L32+Q32+V32 -> 986431.15
B33: IT Costs - security Blackduck | C33: Jonathan W | E33: ='13) IT- Security'!$H$41 -> 43750 | G33: =SUM(E33:F33) -> 43750 | L33: =SUM(H33:K33) -> 0 | M33: =J33 -> 0 | N33: =M33 -> 0 | O33: =N33 -> 0 | P33: =M33 -> 0 | Q33: =SUM(M33:P33) -> 0 | R33: =M33 -> 0 | S33: =R33 -> 0 | T33: =S33 -> 0 | U33: =S33 -> 0 | V33: =SUM(R33:U33) -> 0 | W33: =G33+L33+Q33+V33 -> 43750
B34: IT Costs - laptops etc | C34: Bill Bragg | F34: ='11) IT-Infrastructure'!$I$41-F35 -> 90000 | G34: =SUM(E34:F34) -> 90000 | L34: =SUM(H34:K34) -> 0 | M34: =J34 -> 0 | N34: =M34 -> 0 | O34: =N34 -> 0 | P34: =M34 -> 0 | Q34: =SUM(M34:P34) -> 0 | R34: =M34 -> 0 | S34: =R34 -> 0 | T34: =S34 -> 0 | U34: =S34 -> 0 | V34: =SUM(R34:U34) -> 0 | W34: =G34+L34+Q34+V34 -> 90000
B35: IT Costs - wi fi&special software | C35: Bill Bragg | F35: ='11) IT-Infrastructure'!$I$31+'11) IT-Infrastructure'!I34 -> 20000 | G35: =SUM(E35:F35) -> 20000 | H35: ='11) IT-Infrastructure'!$I$31+'11) IT-Infrastructure'!K34 -> 10000 | I35: ='11) IT-Infrastructure'!$I$31+'11) IT-Infrastructure'!L34 -> 10000 | J35: ='11) IT-Infrastructure'!$I$31+'11) IT-Infrastructure'!M34 -> 20000 | K35: ='11) IT-Infrastructure'!$I$31+'11) IT-Infrastructure'!N34 -> 10000 | L35: =SUM(H35:K35) -> 50000 | M35: =K35 -> 10000 | N35: =M35 -> 10000 | O35: =N35 -> 10000 | P35: =M35 -> 10000 | Q35: =SUM(M35:P35) -> 40000 | R35: =M35 -> 10000 | S35: =R35 -> 10000 | T35: =S35 -> 10000 | U35: =S35 -> 10000 | V35: =SUM(R35:U35) -> 40000 | W35: =G35+L35+Q35+V35 -> 150000
B36: Valuation reviews - BVA+External cost | C36: Heather | F36: =15000+30000 -> 45000 | G36: =SUM(E36:F36) -> 45000 | L36: =SUM(H36:K36) -> 0 | Q36: =SUM(M36:P36) -> 0 | V36: =SUM(R36:U36) -> 0 | W36: =G36+L36+Q36+V36 -> 45000
B37: Legal expenses - external counsel | C37: Nisha | F37: 425000 | G37: =SUM(E37:F37) -> 425000 | L37: =SUM(H37:K37) -> 0 | Q37: =SUM(M37:P37) -> 0 | V37: =SUM(R37:U37) -> 0 | W37: =G37+L37+Q37+V37 -> 425000
B38: Engineering - Agora + other aps | C38: Paul Quinn | F38: ='2) SW Eng'!$I$41 -> 25564.375 | G38: =SUM(E38:F38) -> 25564.375 | H38: ='2) SW Eng'!J41 -> 19164.375 | I38: ='2) SW Eng'!K41 -> 19164.375 | J38: ='2) SW Eng'!L41 -> 19414.375 | K38: ='2) SW Eng'!M41 -> 6914.375 | L38: =SUM(H38:K38) -> 64657.5 | M38: ='2) SW Eng'!N41 -> 3500 | N38: ='2) SW Eng'!O41 -> 3500 | O38: ='2) SW Eng'!P41 -> 3500 | P38: ='2) SW Eng'!Q41 -> 3500 | Q38: =SUM(M38:P38) -> 14000 | R38: ='2) SW Eng'!P41 -> 3500 | S38: ='2) SW Eng'!Q41 -> 3500 | T38: ='2) SW Eng'!R41 -> 3500 | U38: ='2) SW Eng'!S41 -> 3500 | V38: =SUM(R38:U38) -> 14000 | W38: =G38+L38+Q38+V38 -> 118221.88
B39: Operations | C39: Bobinder | E39: ='14) Operations'!$H$41 -> 0 | F39: =E39 -> 0 | G39: =SUM(E39:F39) -> 0 | H39: =E39 -> 0 | I39: =H39 -> 0 | L39: =SUM(H39:K39) -> 0 | Q39: =SUM(M39:P39) -> 0 | V39: =SUM(R39:U39) -> 0 | W39: =G39+L39+Q39+V39 -> 0
B40: Tax - compliance costs | C40: Anu/Harvey | G40: =SUM(E40:F40) -> 0 | I40: 12000 | L40: =SUM(H40:K40) -> 12000 | N40: =I40 -> 12000 | Q40: =SUM(M40:P40) -> 12000 | S40: =I40 -> 12000 | V40: =SUM(R40:U40) -> 12000 | W40: =G40+L40+Q40+V40 -> 36000
B41: Tax - stamp duty | C41: Legal | F41: =7500000*50%*0.2% -> 7500 | G41: =SUM(E41:F41) -> 7500 | L41: =SUM(H41:K41) -> 0 | N41: =I41 -> 0 | Q41: =SUM(M41:P41) -> 0 | S41: =I41 -> 0 | V41: =SUM(R41:U41) -> 0 | W41: =G41+L41+Q41+V41 -> 7500
B42: Other | F42: 25000 | G42: =SUM(E42:F42) -> 25000 | H42: =F42 -> 25000 | I42: =G42 -> 25000 | J42: =H42 -> 25000 | K42: =I42 -> 25000 | L42: =SUM(H42:K42) -> 100000 | M42: =H42 -> 25000 | N42: =I42 -> 25000 | O42: =J42 -> 25000 | P42: =K42 -> 25000 | Q42: =SUM(M42:P42) -> 100000 | R42: =M42 -> 25000 | S42: =N42 -> 25000 | T42: =O42 -> 25000 | U42: =P42 -> 25000 | V42: =SUM(R42:U42) -> 100000 | W42: =G42+L42+Q42+V42 -> 325000
B43: Total Operating costs | F43: =F29+F31+SUM(F32:F42) -> 990202.43 | G43: =G29+G31+SUM(G32:G42) -> 1033952.4 | H43: =H29+H31+SUM(H32:H42) -> 478883.51 | I43: =I29+I31+SUM(I32:I42) -> 490883.51 | J43: =J29+J31+SUM(J32:J42) -> 470827.43 | K43: =K29+K31+SUM(K32:K42) -> 448327.43 | L43: =L29+L31+SUM(L32:L42) -> 1888921.4 | M43: =M29+M31+SUM(M32:M42) -> 459434.36 | ... V43: =V29+V31+SUM(V32:V42) -> 1846976 | W43: =G43+L43+Q43+V43 -> 6577086.7
B44: Total Costs associated with current employees | E44: =E22+E24+E26+E27+E28+E31+E32+E35+E36+E40+E38+E37+E42+E34+E39+E33+E16+E17 -> 43750 | F44: =F22+F24+F26+F27+F28+F31+F32+F35+F36+F40+F38+F37+F42+F34+F39+F33+F16+F17 -> 1246705.7 | G44: =G22+G24+G26+G27+G28+G31+G32+G35+G36+G40+G38+G37+G42+G34+G39+G33+G16+G17 -> 1290455.7 | H44: =H22+H24+H26+H27+H28+H31+H32+H35+H36+H40+H38+H37+H42+H34+H39+H33+H16+H17 -> 478883.36 | I44: =I22+I24+I26+I27+I28+I31+I32+I35+I36+I40+I38+I37+I42+I34+I39+I33+I16+I17 -> 490883.36 | J44: =J22+J24+J26+J27+J28+J31+J32+J35+J36+J40+J38+J37+J42+J34+J39+J33+J16+J17 -> 470827.28 | K44: =K22+K24+K26+K27+K28+K31+K32+K35+K36+K40+K38+K37+K42+K34+K39+K33+K16+K17 -> 448327.28 | L44: =L22+L24+L26+L27+L28+L31+L32+L35+L36+L40+L38+L37+L42+L34+L39+L33+L16+L17 -> 1888921.3 | ... W44: =W22+W24+W26+W27+W28+W31+W32+W35+W36+W40+W38+W37+W42+W34+W39+W33+W16+W17 -> 6833589.5
...

Sheet Recoverable units
A3: DokiPal Units as of September 1, 2019
B5: # in inventory at Doki | C5: # w/ channel Partners | D5: # sold into Market | E5: Sub-total Units | F5: # activated | G5: # active (last 30 days) | H5: # active (last 6 Months) (i.e., pinged server at least once in last 6 months) | I5: Warranty Period Length | J5: # units defective / warranty claim | K5: Cost of Replacements | L5: # Still Under warranty
B6: 3018 | C6: ? | D6: 4982 | E6: 8000 | F6: 2221 | G6: 2221 | H6: 2221 | I6: 12 months | J6: 55 | K6: $65/ unit | L6: All
C8: We don't have visibility on the # of units our distributors/ retailers have in stock | D8: This is the total # of units we sold through wholesale and online channels
E12: =D6-F6 -> 2761
B14: Added by LB:
B15: Invoice price disti would have paid | E15: =180*60% -> 108 | M15: Q for Audrey - why multiply by 40% for returns?
A16: 0.1 | B16: 10% mark up to incentivise partners to return stock | E16: =E15*(1+A16) -> 118.8
B18: % of units able to repurchase | E18: 0.4 | F18: 0.5 | G18: 0.6 | H18: 0.7 | I18: 0.8 | J18: 0.9 | K18: 1 | M18: This is a q for Bobinder?
E20: =($E$12*E18)*$E$16 -> 131202.72 | F20: =($E$12*F18)*$E$16 -> 164003.4 | G20: =($E$12*G18)*$E$16 -> 196804.08 | H20: =($E$12*H18)*$E$16 -> 229604.76 | I20: =($E$12*I18)*$E$16 -> 262405.44 | J20: =($E$12*J18)*$E$16 -> 295206.12 | K20: =($E$12*K18)*$E$16 -> 328006.8 | M20: Will we write these off/keep them for returns/warranty (in which case a double hit to the p&l is showing)?

Sheet Stamp duty
B2: We wanted also to get back to the group on the stamp duty. The current rate of stamp duty is an aggregate of 0.2 percent (0.1 percent payable by each of Seller and Buyer) of the higher of (i) the purchase price or (ii) the value of the stock, which is typically the net asset value of the target as shown in its latest audited accounts. The determination of the purchase price (assuming it exceeds NAV) would (1) take into account any purchase price adjustments e.g. working capital adjustment and (2) include the maximum amount of the earnout. Fyi, there is an opportunity to apply for a refund of excessive stamp duty paid if turns out the actual earnout is less than the maximum, but the period to do so is limited to 2 years.

Sheet 2) SW Eng
A1: Delta Incremental Costs
A3: Headcount | H3: 2019 | J3: 2020 | N3: 2021 | R3: 2022
H4: 43647 | I4: 43739 | J4: 43831 | K4: 43922 | L4: 44013 | M4: 44105 | N4: 44197 | O4: 44287 | P4: 44378 | Q4: 44470 | R4: 44562 | S4: 44652
A5: Submitted by | B5: Department | C5: TBH Title | D5: Description | E5: Hire Date | F5: Location | G5: Base Salary Estimate USD | H5: Q3 | I5: Q4 | J5: Q1 | K5: Q2 | L5: Q3 | M5: Q4 | N5: Q1 | O5: Q2 | P5: Q3 | Q5: Q4 | R5: Q1 | S5: Q2
H6: =IF($E6<I$4,($G6*1.3)/4,0) -> 0 | I6: =IF($E6<J$4,($G6*1.3)/4,0) -> 0 | J6: =IF($E6<K$4,($G6*1.3)/4,0) -> 0 | K6: =IF($E6<L$4,($G6*1.3)/4,0) -> 0 | L6: =IF($E6<M$4,($G6*1.3)/4,0) -> 0 | M6: =IF($E6<N$4,($G6*1.3)/4,0) -> 0 | N6: =IF($E6<O$4,($G6*1.3)/4,0) -> 0 | O6: =IF($E6<P$4,($G6*1.3)/4,0) -> 0 | ... R6: =IF($E6<S$4,($G6*1.3)/4,0) -> 0 | S6: =IF($E6<S$4,($G6*1.3)/4,0) -> 0
H7: =IF($E7<I$4,($G7*1.3)/4,0) -> 0 | I7: =IF($E7<J$4,($G7*1.3)/4,0) -> 0 | J7: =IF($E7<K$4,($G7*1.3)/4,0) -> 0 | K7: =IF($E7<L$4,($G7*1.3)/4,0) -> 0 | L7: =IF($E7<M$4,($G7*1.3)/4,0) -> 0 | M7: =IF($E7<N$4,($G7*1.3)/4,0) -> 0 | N7: =IF($E7<O$4,($G7*1.3)/4,0) -> 0 | O7: =IF($E7<P$4,($G7*1.3)/4,0) -> 0 | ... R7: =IF($E7<S$4,($G7*1.3)/4,0) -> 0 | S7: =IF($E7<S$4,($G7*1.3)/4,0) -> 0
H8: =IF($E8<I$4,($G8*1.3)/4,0) -> 0 | I8: =IF($E8<J$4,($G8*1.3)/4,0) -> 0 | J8: =IF($E8<K$4,($G8*1.3)/4,0) -> 0 | K8: =IF($E8<L$4,($G8*1.3)/4,0) -> 0 | L8: =IF($E8<M$4,($G8*1.3)/4,0) -> 0 | M8: =IF($E8<N$4,($G8*1.3)/4,0) -> 0 | N8: =IF($E8<O$4,($G8*1.3)/4,0) -> 0 | O8: =IF($E8<P$4,($G8*1.3)/4,0) -> 0 | ... R8: =IF($E8<S$4,($G8*1.3)/4,0) -> 0 | S8: =IF($E8<S$4,($G8*1.3)/4,0) -> 0
H9: =IF($E9<I$4,($G9*1.3)/4,0) -> 0 | I9: =IF($E9<J$4,($G9*1.3)/4,0) -> 0 | J9: =IF($E9<K$4,($G9*1.3)/4,0) -> 0 | K9: =IF($E9<L$4,($G9*1.3)/4,0) -> 0 | L9: =IF($E9<M$4,($G9*1.3)/4,0) -> 0 | M9: =IF($E9<N$4,($G9*1.3)/4,0) -> 0 | N9: =IF($E9<O$4,($G9*1.3)/4,0) -> 0 | O9: =IF($E9<P$4,($G9*1.3)/4,0) -> 0 | ... R9: =IF($E9<S$4,($G9*1.3)/4,0) -> 0 | S9: =IF($E9<S$4,($G9*1.3)/4,0) -> 0
H10: =IF($E10<I$4,($G10*1.3)/4,0) -> 0 | I10: =IF($E10<J$4,($G10*1.3)/4,0) -> 0 | J10: =IF($E10<K$4,($G10*1.3)/4,0) -> 0 | K10: =IF($E10<L$4,($G10*1.3)/4,0) -> 0 | L10: =IF($E10<M$4,($G10*1.3)/4,0) -> 0 | M10: =IF($E10<N$4,($G10*1.3)/4,0) -> 0 | N10: =IF($E10<O$4,($G10*1.3)/4,0) -> 0 | O10: =IF($E10<P$4,($G10*1.3)/4,0) -> 0 | ... R10: =IF($E10<S$4,($G10*1.3)/4,0) -> 0 | S10: =IF($E10<S$4,($G10*1.3)/4,0) -> 0
H11: =IF($E11<I$4,($G11*1.3)/4,0) -> 0 | I11: =IF($E11<J$4,($G11*1.3)/4,0) -> 0 | J11: =IF($E11<K$4,($G11*1.3)/4,0) -> 0 | K11: =IF($E11<L$4,($G11*1.3)/4,0) -> 0 | L11: =IF($E11<M$4,($G11*1.3)/4,0) -> 0 | M11: =IF($E11<N$4,($G11*1.3)/4,0) -> 0 | N11: =IF($E11<O$4,($G11*1.3)/4,0) -> 0 | O11: =IF($E11<P$4,($G11*1.3)/4,0) -> 0 | ... R11: =IF($E11<S$4,($G11*1.3)/4,0) -> 0 | S11: =IF($E11<S$4,($G11*1.3)/4,0) -> 0
H12: =IF($E12<I$4,($G12*1.3)/4,0) -> 0 | I12: =IF($E12<J$4,($G12*1.3)/4,0) -> 0 | J12: =IF($E12<K$4,($G12*1.3)/4,0) -> 0 | K12: =IF($E12<L$4,($G12*1.3)/4,0) -> 0 | L12: =IF($E12<M$4,($G12*1.3)/4,0) -> 0 | M12: =IF($E12<N$4,($G12*1.3)/4,0) -> 0 | N12: =IF($E12<O$4,($G12*1.3)/4,0) -> 0 | O12: =IF($E12<P$4,($G12*1.3)/4,0) -> 0 | ... R12: =IF($E12<S$4,($G12*1.3)/4,0) -> 0 | S12: =IF($E12<S$4,($G12*1.3)/4,0) -> 0
H13: =IF($E13<I$4,($G13*1.3)/4,0) -> 0 | I13: =IF($E13<J$4,($G13*1.3)/4,0) -> 0 | J13: =IF($E13<K$4,($G13*1.3)/4,0) -> 0 | K13: =IF($E13<L$4,($G13*1.3)/4,0) -> 0 | L13: =IF($E13<M$4,($G13*1.3)/4,0) -> 0 | M13: =IF($E13<N$4,($G13*1.3)/4,0) -> 0 | N13: =IF($E13<O$4,($G13*1.3)/4,0) -> 0 | O13: =IF($E13<P$4,($G13*1.3)/4,0) -> 0 | ... R13: =IF($E13<S$4,($G13*1.3)/4,0) -> 0 | S13: =IF($E13<S$4,($G13*1.3)/4,0) -> 0
H14: =IF($E14<I$4,($G14*1.3)/4,0) -> 0 | I14: =IF($E14<J$4,($G14*1.3)/4,0) -> 0 | J14: =IF($E14<K$4,($G14*1.3)/4,0) -> 0 | K14: =IF($E14<L$4,($G14*1.3)/4,0) -> 0 | L14: =IF($E14<M$4,($G14*1.3)/4,0) -> 0 | M14: =IF($E14<N$4,($G14*1.3)/4,0) -> 0 | N14: =IF($E14<O$4,($G14*1.3)/4,0) -> 0 | O14: =IF($E14<P$4,($G14*1.3)/4,0) -> 0 | ... R14: =IF($E14<S$4,($G14*1.3)/4,0) -> 0 | S14: =IF($E14<S$4,($G14*1.3)/4,0) -> 0
H15: =IF($E15<I$4,($G15*1.3)/4,0) -> 0 | I15: =IF($E15<J$4,($G15*1.3)/4,0) -> 0 | J15: =IF($E15<K$4,($G15*1.3)/4,0) -> 0 | K15: =IF($E15<L$4,($G15*1.3)/4,0) -> 0 | L15: =IF($E15<M$4,($G15*1.3)/4,0) -> 0 | M15: =IF($E15<N$4,($G15*1.3)/4,0) -> 0 | N15: =IF($E15<O$4,($G15*1.3)/4,0) -> 0 | O15: =IF($E15<P$4,($G15*1.3)/4,0) -> 0 | ... R15: =IF($E15<S$4,($G15*1.3)/4,0) -> 0 | S15: =IF($E15<S$4,($G15*1.3)/4,0) -> 0
H16: =IF($E16<I$4,($G16*1.3)/4,0) -> 0 | I16: =IF($E16<J$4,($G16*1.3)/4,0) -> 0 | J16: =IF($E16<K$4,($G16*1.3)/4,0) -> 0 | K16: =IF($E16<L$4,($G16*1.3)/4,0) -> 0 | L16: =IF($E16<M$4,($G16*1.3)/4,0) -> 0 | M16: =IF($E16<N$4,($G16*1.3)/4,0) -> 0 | N16: =IF($E16<O$4,($G16*1.3)/4,0) -> 0 | O16: =IF($E16<P$4,($G16*1.3)/4,0) -> 0 | ... R16: =IF($E16<S$4,($G16*1.3)/4,0) -> 0 | S16: =IF($E16<S$4,($G16*1.3)/4,0) -> 0
H17: =IF($E17<I$4,($G17*1.3)/4,0) -> 0 | I17: =IF($E17<J$4,($G17*1.3)/4,0) -> 0 | J17: =IF($E17<K$4,($G17*1.3)/4,0) -> 0 | K17: =IF($E17<L$4,($G17*1.3)/4,0) -> 0 | L17: =IF($E17<M$4,($G17*1.3)/4,0) -> 0 | M17: =IF($E17<N$4,($G17*1.3)/4,0) -> 0 | N17: =IF($E17<O$4,($G17*1.3)/4,0) -> 0 | O17: =IF($E17<P$4,($G17*1.3)/4,0) -> 0 | ... R17: =IF($E17<S$4,($G17*1.3)/4,0) -> 0 | S17: =IF($E17<S$4,($G17*1.3)/4,0) -> 0
... H24: =IF($E24<I$4,($G24*1.3)/4,0) -> 0 | I24: =IF($E24<J$4,($G24*1.3)/4,0) -> 0 | J24: =IF($E24<K$4,($G24*1.3)/4,0) -> 0 | K24: =IF($E24<L$4,($G24*1.3)/4,0) -> 0 | L24: =IF($E24<M$4,($G24*1.3)/4,0) -> 0 | M24: =IF($E24<N$4,($G24*1.3)/4,0) -> 0 | N24: =IF($E24<O$4,($G24*1.3)/4,0) -> 0 | O24: =IF($E24<P$4,($G24*1.3)/4,0) -> 0 | ... R24: =IF($E24<S$4,($G24*1.3)/4,0) -> 0 | S24: =IF($E24<S$4,($G24*1.3)/4,0) -> 0
H25: =SUM(H6:H24) -> 0 | I25: =SUM(I6:I24) -> 0 | J25: =SUM(J6:J24) -> 0 | K25: =SUM(K6:K24) -> 0 | L25: =SUM(L6:L24) -> 0 | M25: =SUM(M6:M24) -> 0 | N25: =SUM(N6:N24) -> 0 | O25: =SUM(O6:O24) -> 0 | ... S25: =SUM(S6:S24) -> 0
A27: Non Headcount | H27: 2019 | J27: 2020 | N27: 2021 | R27: 2022
A28: Submitted by | B28: Department | C28: Description of Spend | D28: Justification | G28: Total Cost Estimate | H28: Q3 | I28: Q4 | J28: Q1 | K28: Q2 | L28: Q3 | M28: Q4 | N28: Q1 | O28: Q2 | P28: Q3 | Q28: Q4 | R28: Q1 | S28: Q2
A29: LB (Based on email from Paul Quinn) | B29: Agora | C29: Set up a new Fitbit owned Agora account - 10k to 50k | D29: Shares video calling API use with another company. This may incur unforeseen costs as we support their existing in-market devices for a yea | I29: =50000/4 -> 12500 | J29: =I29 -> 12500 | K29: =J29 -> 12500 | L29: =K29 -> 12500
A31: Engineering | B31: licensing for devt tools - current employees | C31: Licensing for development tools | G31: $500 per engineering employee per year listed above (new hire) - for above people in Hong Kong office | I31: ='I. TECH'!J26*(500/4) -> 750 | J31: ='I. TECH'!K26*(500/4) -> 1500 | K31: ='I. TECH'!L26*(500/4) -> 1500 | L31: ='I. TECH'!M26*(500/4) -> 1750 | M31: ='I. TECH'!N26*(500/4) -> 1750 | N31: ='I. TECH'!O26*(500/4) -> 1750 | O31: ='I. TECH'!P26*(500/4) -> 1750 | P31: ='I. TECH'!Q26*(500/4) -> 1750 | ... S31: ='I. TECH'!T26*(500/4) -> 1750
B32: licensing for devt tools - new employees | G32: $500 per engineering employee per year listed above (existing ) - for above people in Hong Kong office | I32: =14*(500/4) -> 1750 | J32: =14*(500/4) -> 1750 | K32: =14*(500/4) -> 1750 | L32: =14*(500/4) -> 1750 | M32: =14*(500/4) -> 1750 | N32: =14*(500/4) -> 1750 | O32: =14*(500/4) -> 1750 | P32: =14*(500/4) -> 1750 | ... S32: =14*(500/4) -> 1750
A33: Ryan Krems | B33: Product | C33: Recruiting Budget | D33: Need to get new-hires on-board - 2 months of average salary per new hire
A35: adde by LB based on email from Ryan | B35: For 4Q2019 only as we will want to support the PRC mode for a limited time only. | D35: alibaba cloud | I35: 1000
A36: adde by LB based on email from Ryan | B36: Github - Yes - Through 4Q2020 (small amount, want to make sure it isn't effecting their work flow for existing users) | I36: =344/8*3 -> 129 | J36: =I36 -> 129 | K36: =J36 -> 129 | L36: =K36 -> 129 | M36: =L36 -> 129
A37: adde by LB based on email from Ryan | B37: Mailchimp - Yes - Through 4Q2020 (would expect this to be a much smaller amount that they were having before) | I37: =1600/8*3 -> 600 | J37: =I37 -> 600 | K37: =J37 -> 600 | L37: =K37 -> 600 | M37: =L37 -> 600
A38: adde by LB based on email from Ryan | B38: Linode - Yes - Through 4Q2020 (not sure what they are using for, but a really small amount) | I38: =80/8*3 -> 30 | J38: =I38 -> 30 | K38: =J38 -> 30 | L38: =K38 -> 30 | M38: =L38 -> 30
A39: adde by LB based on email from Ryan | B39: AWS - Yes - Through 4Q2020 (this is to support their current user base) | I39: =7081/8*3 -> 2655.375 | J39: =I39 -> 2655.375 | K39: =J39 -> 2655.375 | L39: =K39 -> 2655.375 | M39: =L39 -> 2655.375
A40: adde by LB based on email from Ryan | B40: Google Cloud - Yes - Through 4Q2019 (expect these to all be rolled over to Fitbit infra by EOY) | I40: =16400/8*3 -> 6150
G41: =SUM(G29:G40) -> 0 | H41: =SUM(H29:H34) -> 0 | I41: =SUM(I29:I40) -> 25564.375 | J41: =SUM(J29:J40) -> 19164.375 | K41: =SUM(K29:K40) -> 19164.375 | L41: =SUM(L29:L40) -> 19414.375 | M41: =SUM(M29:M40) -> 6914.375 | N41: =SUM(N29:N40) -> 3500 | O41: =SUM(O29:O40) -> 3500 | P41: =SUM(P29:P40) -> 3500 | ... S41: =SUM(S29:S40) -> 3500

Sheet 4) Accounting
A1: Delta Incremental Costs
A3: Headcount | H3: 2019 | J3: 2020 | N3: 2021 | R3: 2022
H4: 43647 | I4: 43739 | J4: 43831 | K4: 43922 | L4: 44013 | M4: 44105 | N4: 44197 | O4: 44287 | P4: 44378 | Q4: 44470 | R4: 44562 | S4: 44652
A5: Submitted by | B5: Department | C5: TBH Title | D5: Description | E5: Hire Date | F5: Location | G5: Base Salary Estimate USD | H5: Q3 | I5: Q4 | J5: Q1 | K5: Q2 | L5: Q3 | M5: Q4 | N5: Q1 | O5: Q2 | P5: Q3 | Q5: Q4 | R5: Q1 | S5: Q2
H6: =IF($E6<I$4,($G6*1.3)/4,0) -> 0 | I6: =IF($E6<J$4,($G6*1.3)/4,0) -> 0 | J6: =IF($E6<K$4,($G6*1.3)/4,0) -> 0 | K6: =IF($E6<L$4,($G6*1.3)/4,0) -> 0 | L6: =IF($E6<M$4,($G6*1.3)/4,0) -> 0 | M6: =IF($E6<N$4,($G6*1.3)/4,0) -> 0 | N6: =IF($E6<O$4,($G6*1.3)/4,0) -> 0 | O6: =IF($E6<P$4,($G6*1.3)/4,0) -> 0 | ... R6: =IF($E6<S$4,($G6*1.3)/4,0) -> 0 | S6: =IF($E6<S$4,($G6*1.3)/4,0) -> 0
H7: =IF($E7<I$4,($G7*1.3)/4,0) -> 0 | I7: =IF($E7<J$4,($G7*1.3)/4,0) -> 0 | J7: =IF($E7<K$4,($G7*1.3)/4,0) -> 0 | K7: =IF($E7<L$4,($G7*1.3)/4,0) -> 0 | L7: =IF($E7<M$4,($G7*1.3)/4,0) -> 0 | M7: =IF($E7<N$4,($G7*1.3)/4,0) -> 0 | N7: =IF($E7<O$4,($G7*1.3)/4,0) -> 0 | O7: =IF($E7<P$4,($G7*1.3)/4,0) -> 0 | ... R7: =IF($E7<S$4,($G7*1.3)/4,0) -> 0 | S7: =IF($E7<S$4,($G7*1.3)/4,0) -> 0
H8: =IF($E8<I$4,($G8*1.3)/4,0) -> 0 | I8: =IF($E8<J$4,($G8*1.3)/4,0) -> 0 | J8: =IF($E8<K$4,($G8*1.3)/4,0) -> 0 | K8: =IF($E8<L$4,($G8*1.3)/4,0) -> 0 | L8: =IF($E8<M$4,($G8*1.3)/4,0) -> 0 | M8: =IF($E8<N$4,($G8*1.3)/4,0) -> 0 | N8: =IF($E8<O$4,($G8*1.3)/4,0) -> 0 | O8: =IF($E8<P$4,($G8*1.3)/4,0) -> 0 | ... R8: =IF($E8<S$4,($G8*1.3)/4,0) -> 0 | S8: =IF($E8<S$4,($G8*1.3)/4,0) -> 0
H9: =IF($E9<I$4,($G9*1.3)/4,0) -> 0 | I9: =IF($E9<J$4,($G9*1.3)/4,0) -> 0 | J9: =IF($E9<K$4,($G9*1.3)/4,0) -> 0 | K9: =IF($E9<L$4,($G9*1.3)/4,0) -> 0 | L9: =IF($E9<M$4,($G9*1.3)/4,0) -> 0 | M9: =IF($E9<N$4,($G9*1.3)/4,0) -> 0 | N9: =IF($E9<O$4,($G9*1.3)/4,0) -> 0 | O9: =IF($E9<P$4,($G9*1.3)/4,0) -> 0 | ... R9: =IF($E9<S$4,($G9*1.3)/4,0) -> 0 | S9: =IF($E9<S$4,($G9*1.3)/4,0) -> 0
H10: =IF($E10<I$4,($G10*1.3)/4,0) -> 0 | I10: =IF($E10<J$4,($G10*1.3)/4,0) -> 0 | J10: =IF($E10<K$4,($G10*1.3)/4,0) -> 0 | K10: =IF($E10<L$4,($G10*1.3)/4,0) -> 0 | L10: =IF($E10<M$4,($G10*1.3)/4,0) -> 0 | M10: =IF($E10<N$4,($G10*1.3)/4,0) -> 0 | N10: =IF($E10<O$4,($G10*1.3)/4,0) -> 0 | O10: =IF($E10<P$4,($G10*1.3)/4,0) -> 0 | ... R10: =IF($E10<S$4,($G10*1.3)/4,0) -> 0 | S10: =IF($E10<S$4,($G10*1.3)/4,0) -> 0
H11: =IF($E11<I$4,($G11*1.3)/4,0) -> 0 | I11: =IF($E11<J$4,($G11*1.3)/4,0) -> 0 | J11: =IF($E11<K$4,($G11*1.3)/4,0) -> 0 | K11: =IF($E11<L$4,($G11*1.3)/4,0) -> 0 | L11: =IF($E11<M$4,($G11*1.3)/4,0) -> 0 | M11: =IF($E11<N$4,($G11*1.3)/4,0) -> 0 | N11: =IF($E11<O$4,($G11*1.3)/4,0) -> 0 | O11: =IF($E11<P$4,($G11*1.3)/4,0) -> 0 | ... R11: =IF($E11<S$4,($G11*1.3)/4,0) -> 0 | S11: =IF($E11<S$4,($G11*1.3)/4,0) -> 0
H12: =IF($E12<I$4,($G12*1.3)/4,0) -> 0 | I12: =IF($E12<J$4,($G12*1.3)/4,0) -> 0 | J12: =IF($E12<K$4,($G12*1.3)/4,0) -> 0 | K12: =IF($E12<L$4,($G12*1.3)/4,0) -> 0 | L12: =IF($E12<M$4,($G12*1.3)/4,0) -> 0 | M12: =IF($E12<N$4,($G12*1.3)/4,0) -> 0 | N12: =IF($E12<O$4,($G12*1.3)/4,0) -> 0 | O12: =IF($E12<P$4,($G12*1.3)/4,0) -> 0 | ... R12: =IF($E12<S$4,($G12*1.3)/4,0) -> 0 | S12: =IF($E12<S$4,($G12*1.3)/4,0) -> 0
H13: =IF($E13<I$4,($G13*1.3)/4,0) -> 0 | I13: =IF($E13<J$4,($G13*1.3)/4,0) -> 0 | J13: =IF($E13<K$4,($G13*1.3)/4,0) -> 0 | K13: =IF($E13<L$4,($G13*1.3)/4,0) -> 0 | L13: =IF($E13<M$4,($G13*1.3)/4,0) -> 0 | M13: =IF($E13<N$4,($G13*1.3)/4,0) -> 0 | N13: =IF($E13<O$4,($G13*1.3)/4,0) -> 0 | O13: =IF($E13<P$4,($G13*1.3)/4,0) -> 0 | ... R13: =IF($E13<S$4,($G13*1.3)/4,0) -> 0 | S13: =IF($E13<S$4,($G13*1.3)/4,0) -> 0
H14: =IF($E14<I$4,($G14*1.3)/4,0) -> 0 | I14: =IF($E14<J$4,($G14*1.3)/4,0) -> 0 | J14: =IF($E14<K$4,($G14*1.3)/4,0) -> 0 | K14: =IF($E14<L$4,($G14*1.3)/4,0) -> 0 | L14: =IF($E14<M$4,($G14*1.3)/4,0) -> 0 | M14: =IF($E14<N$4,($G14*1.3)/4,0) -> 0 | N14: =IF($E14<O$4,($G14*1.3)/4,0) -> 0 | O14: =IF($E14<P$4,($G14*1.3)/4,0) -> 0 | ... R14: =IF($E14<S$4,($G14*1.3)/4,0) -> 0 | S14: =IF($E14<S$4,($G14*1.3)/4,0) -> 0
H15: =IF($E15<I$4,($G15*1.3)/4,0) -> 0 | I15: =IF($E15<J$4,($G15*1.3)/4,0) -> 0 | J15: =IF($E15<K$4,($G15*1.3)/4,0) -> 0 | K15: =IF($E15<L$4,($G15*1.3)/4,0) -> 0 | L15: =IF($E15<M$4,($G15*1.3)/4,0) -> 0 | M15: =IF($E15<N$4,($G15*1.3)/4,0) -> 0 | N15: =IF($E15<O$4,($G15*1.3)/4,0) -> 0 | O15: =IF($E15<P$4,($G15*1.3)/4,0) -> 0 | ... R15: =IF($E15<S$4,($G15*1.3)/4,0) -> 0 | S15: =IF($E15<S$4,($G15*1.3)/4,0) -> 0
H16: =IF($E16<I$4,($G16*1.3)/4,0) -> 0 | I16: =IF($E16<J$4,($G16*1.3)/4,0) -> 0 | J16: =IF($E16<K$4,($G16*1.3)/4,0) -> 0 | K16: =IF($E16<L$4,($G16*1.3)/4,0) -> 0 | L16: =IF($E16<M$4,($G16*1.3)/4,0) -> 0 | M16: =IF($E16<N$4,($G16*1.3)/4,0) -> 0 | N16: =IF($E16<O$4,($G16*1.3)/4,0) -> 0 | O16: =IF($E16<P$4,($G16*1.3)/4,0) -> 0 | ... R16: =IF($E16<S$4,($G16*1.3)/4,0) -> 0 | S16: =IF($E16<S$4,($G16*1.3)/4,0) -> 0
H17: =IF($E17<I$4,($G17*1.3)/4,0) -> 0 | I17: =IF($E17<J$4,($G17*1.3)/4,0) -> 0 | J17: =IF($E17<K$4,($G17*1.3)/4,0) -> 0 | K17: =IF($E17<L$4,($G17*1.3)/4,0) -> 0 | L17: =IF($E17<M$4,($G17*1.3)/4,0) -> 0 | M17: =IF($E17<N$4,($G17*1.3)/4,0) -> 0 | N17: =IF($E17<O$4,($G17*1.3)/4,0) -> 0 | O17: =IF($E17<P$4,($G17*1.3)/4,0) -> 0 | ... R17: =IF($E17<S$4,($G17*1.3)/4,0) -> 0 | S17: =IF($E17<S$4,($G17*1.3)/4,0) -> 0
... H24: =IF($E24<I$4,($G24*1.3)/4,0) -> 0 | I24: =IF($E24<J$4,($G24*1.3)/4,0) -> 0 | J24: =IF($E24<K$4,($G24*1.3)/4,0) -> 0 | K24: =IF($E24<L$4,($G24*1.3)/4,0) -> 0 | L24: =IF($E24<M$4,($G24*1.3)/4,0) -> 0 | M24: =IF($E24<N$4,($G24*1.3)/4,0) -> 0 | N24: =IF($E24<O$4,($G24*1.3)/4,0) -> 0 | O24: =IF($E24<P$4,($G24*1.3)/4,0) -> 0 | ... R24: =IF($E24<S$4,($G24*1.3)/4,0) -> 0 | S24: =IF($E24<S$4,($G24*1.3)/4,0) -> 0
H25: =SUM(H6:H24) -> 0 | I25: =SUM(I6:I24) -> 0 | J25: =SUM(J6:J24) -> 0 | K25: =SUM(K6:K24) -> 0 | L25: =SUM(L6:L24) -> 0 | M25: =SUM(M6:M24) -> 0 | N25: =SUM(N6:N24) -> 0 | O25: =SUM(O6:O24) -> 0 | ... S25: =SUM(S6:S24) -> 0
A27: Non Headcount | H27: 2019 | J27: 2020 | N27: 2021 | R27: 2022
A28: Submitted by | B28: Department | C28: Description of Spend | D28: Justification | G28: Total Cost Estimate | H28: Q3 | I28: Q4 | J28: Q1 | K28: Q2 | L28: Q3 | M28: Q4 | N28: Q1 | O28: Q2 | P28: Q3 | Q28: Q4 | R28: Q1 | S28: Q2
A29: Heather | B29: Accounting | C29: Valuation PPA | D29: Valuation of Intangibles & Goodwill | G29: =I29 -> 15000 | I29: 15000
A30: Heather | B30: Accounting | C30: GT PPA Review | D30: External Audit Review of Valuation | G30: =I30 -> 30000 | I30: 30000
G41: =SUM(G29:G40) -> 45000 | H41: =SUM(H29:H34) -> 0 | I41: =SUM(I29:I34) -> 45000 | J41: =SUM(J29:J34) -> 0 | K41: =SUM(K29:K34) -> 0 | L41: =SUM(L29:L34) -> 0 | M41: =SUM(M29:M34) -> 0 | N41: =SUM(N29:N34) -> 0 | O41: =SUM(O29:O34) -> 0 | ... S41: =SUM(S29:S34) -> 0

Sheet 8) Facilities
A1: Delta Incremental Costs
A3: Headcount | H3: 2019 | J3: 2020 | N3: 2021 | R3: 2022
H4: 43647 | I4: 43739 | J4: 43831 | K4: 43922 | L4: 44013 | M4: 44105 | N4: 44197 | O4: 44287 | P4: 44378 | Q4: 44470 | R4: 44562 | S4: 44652
A5: Submitted by | B5: Department | C5: TBH Title | D5: Description | E5: Hire Date | F5: Location | G5: Base Salary Estimate USD | H5: Q3 | I5: Q4 | J5: Q1 | K5: Q2 | L5: Q3 | M5: Q4 | N5: Q1 | O5: Q2 | P5: Q3 | Q5: Q4 | R5: Q1 | S5: Q2
H6: =IF($E6<I$4,($G6*1.3)/4,0) -> 0 | I6: =IF($E6<J$4,($G6*1.3)/4,0) -> 0 | J6: =IF($E6<K$4,($G6*1.3)/4,0) -> 0 | K6: =IF($E6<L$4,($G6*1.3)/4,0) -> 0 | L6: =IF($E6<M$4,($G6*1.3)/4,0) -> 0 | M6: =IF($E6<N$4,($G6*1.3)/4,0) -> 0 | N6: =IF($E6<O$4,($G6*1.3)/4,0) -> 0 | O6: =IF($E6<P$4,($G6*1.3)/4,0) -> 0 | ... R6: =IF($E6<S$4,($G6*1.3)/4,0) -> 0 | S6: =IF($E6<S$4,($G6*1.3)/4,0) -> 0
H7: =IF($E7<I$4,($G7*1.3)/4,0) -> 0 | I7: =IF($E7<J$4,($G7*1.3)/4,0) -> 0 | J7: =IF($E7<K$4,($G7*1.3)/4,0) -> 0 | K7: =IF($E7<L$4,($G7*1.3)/4,0) -> 0 | L7: =IF($E7<M$4,($G7*1.3)/4,0) -> 0 | M7: =IF($E7<N$4,($G7*1.3)/4,0) -> 0 | N7: =IF($E7<O$4,($G7*1.3)/4,0) -> 0 | O7: =IF($E7<P$4,($G7*1.3)/4,0) -> 0 | ... R7: =IF($E7<S$4,($G7*1.3)/4,0) -> 0 | S7: =IF($E7<S$4,($G7*1.3)/4,0) -> 0
H8: =IF($E8<I$4,($G8*1.3)/4,0) -> 0 | I8: =IF($E8<J$4,($G8*1.3)/4,0) -> 0 | J8: =IF($E8<K$4,($G8*1.3)/4,0) -> 0 | K8: =IF($E8<L$4,($G8*1.3)/4,0) -> 0 | L8: =IF($E8<M$4,($G8*1.3)/4,0) -> 0 | M8: =IF($E8<N$4,($G8*1.3)/4,0) -> 0 | N8: =IF($E8<O$4,($G8*1.3)/4,0) -> 0 | O8: =IF($E8<P$4,($G8*1.3)/4,0) -> 0 | ... R8: =IF($E8<S$4,($G8*1.3)/4,0) -> 0 | S8: =IF($E8<S$4,($G8*1.3)/4,0) -> 0
H9: =IF($E9<I$4,($G9*1.3)/4,0) -> 0 | I9: =IF($E9<J$4,($G9*1.3)/4,0) -> 0 | J9: =IF($E9<K$4,($G9*1.3)/4,0) -> 0 | K9: =IF($E9<L$4,($G9*1.3)/4,0) -> 0 | L9: =IF($E9<M$4,($G9*1.3)/4,0) -> 0 | M9: =IF($E9<N$4,($G9*1.3)/4,0) -> 0 | N9: =IF($E9<O$4,($G9*1.3)/4,0) -> 0 | O9: =IF($E9<P$4,($G9*1.3)/4,0) -> 0 | ... R9: =IF($E9<S$4,($G9*1.3)/4,0) -> 0 | S9: =IF($E9<S$4,($G9*1.3)/4,0) -> 0
H10: =IF($E10<I$4,($G10*1.3)/4,0) -> 0 | I10: =IF($E10<J$4,($G10*1.3)/4,0) -> 0 | J10: =IF($E10<K$4,($G10*1.3)/4,0) -> 0 | K10: =IF($E10<L$4,($G10*1.3)/4,0) -> 0 | L10: =IF($E10<M$4,($G10*1.3)/4,0) -> 0 | M10: =IF($E10<N$4,($G10*1.3)/4,0) -> 0 | N10: =IF($E10<O$4,($G10*1.3)/4,0) -> 0 | O10: =IF($E10<P$4,($G10*1.3)/4,0) -> 0 | ... R10: =IF($E10<S$4,($G10*1.3)/4,0) -> 0 | S10: =IF($E10<S$4,($G10*1.3)/4,0) -> 0
H11: =IF($E11<I$4,($G11*1.3)/4,0) -> 0 | I11: =IF($E11<J$4,($G11*1.3)/4,0) -> 0 | J11: =IF($E11<K$4,($G11*1.3)/4,0) -> 0 | K11: =IF($E11<L$4,($G11*1.3)/4,0) -> 0 | L11: =IF($E11<M$4,($G11*1.3)/4,0) -> 0 | M11: =IF($E11<N$4,($G11*1.3)/4,0) -> 0 | N11: =IF($E11<O$4,($G11*1.3)/4,0) -> 0 | O11: =IF($E11<P$4,($G11*1.3)/4,0) -> 0 | ... R11: =IF($E11<S$4,($G11*1.3)/4,0) -> 0 | S11: =IF($E11<S$4,($G11*1.3)/4,0) -> 0
H12: =IF($E12<I$4,($G12*1.3)/4,0) -> 0 | I12: =IF($E12<J$4,($G12*1.3)/4,0) -> 0 | J12: =IF($E12<K$4,($G12*1.3)/4,0) -> 0 | K12: =IF($E12<L$4,($G12*1.3)/4,0) -> 0 | L12: =IF($E12<M$4,($G12*1.3)/4,0) -> 0 | M12: =IF($E12<N$4,($G12*1.3)/4,0) -> 0 | N12: =IF($E12<O$4,($G12*1.3)/4,0) -> 0 | O12: =IF($E12<P$4,($G12*1.3)/4,0) -> 0 | ... R12: =IF($E12<S$4,($G12*1.3)/4,0) -> 0 | S12: =IF($E12<S$4,($G12*1.3)/4,0) -> 0
H13: =IF($E13<I$4,($G13*1.3)/4,0) -> 0 | I13: =IF($E13<J$4,($G13*1.3)/4,0) -> 0 | J13: =IF($E13<K$4,($G13*1.3)/4,0) -> 0 | K13: =IF($E13<L$4,($G13*1.3)/4,0) -> 0 | L13: =IF($E13<M$4,($G13*1.3)/4,0) -> 0 | M13: =IF($E13<N$4,($G13*1.3)/4,0) -> 0 | N13: =IF($E13<O$4,($G13*1.3)/4,0) -> 0 | O13: =IF($E13<P$4,($G13*1.3)/4,0) -> 0 | ... R13: =IF($E13<S$4,($G13*1.3)/4,0) -> 0 | S13: =IF($E13<S$4,($G13*1.3)/4,0) -> 0
H14: =IF($E14<I$4,($G14*1.3)/4,0) -> 0 | I14: =IF($E14<J$4,($G14*1.3)/4,0) -> 0 | J14: =IF($E14<K$4,($G14*1.3)/4,0) -> 0 | K14: =IF($E14<L$4,($G14*1.3)/4,0) -> 0 | L14: =IF($E14<M$4,($G14*1.3)/4,0) -> 0 | M14: =IF($E14<N$4,($G14*1.3)/4,0) -> 0 | N14: =IF($E14<O$4,($G14*1.3)/4,0) -> 0 | O14: =IF($E14<P$4,($G14*1.3)/4,0) -> 0 | ... R14: =IF($E14<S$4,($G14*1.3)/4,0) -> 0 | S14: =IF($E14<S$4,($G14*1.3)/4,0) -> 0
H15: =IF($E15<I$4,($G15*1.3)/4,0) -> 0 | I15: =IF($E15<J$4,($G15*1.3)/4,0) -> 0 | J15: =IF($E15<K$4,($G15*1.3)/4,0) -> 0 | K15: =IF($E15<L$4,($G15*1.3)/4,0) -> 0 | L15: =IF($E15<M$4,($G15*1.3)/4,0) -> 0 | M15: =IF($E15<N$4,($G15*1.3)/4,0) -> 0 | N15: =IF($E15<O$4,($G15*1.3)/4,0) -> 0 | O15: =IF($E15<P$4,($G15*1.3)/4,0) -> 0 | ... R15: =IF($E15<S$4,($G15*1.3)/4,0) -> 0 | S15: =IF($E15<S$4,($G15*1.3)/4,0) -> 0
H16: =IF($E16<I$4,($G16*1.3)/4,0) -> 0 | I16: =IF($E16<J$4,($G16*1.3)/4,0) -> 0 | J16: =IF($E16<K$4,($G16*1.3)/4,0) -> 0 | K16: =IF($E16<L$4,($G16*1.3)/4,0) -> 0 | L16: =IF($E16<M$4,($G16*1.3)/4,0) -> 0 | M16: =IF($E16<N$4,($G16*1.3)/4,0) -> 0 | N16: =IF($E16<O$4,($G16*1.3)/4,0) -> 0 | O16: =IF($E16<P$4,($G16*1.3)/4,0) -> 0 | ... R16: =IF($E16<S$4,($G16*1.3)/4,0) -> 0 | S16: =IF($E16<S$4,($G16*1.3)/4,0) -> 0
H17: =IF($E17<I$4,($G17*1.3)/4,0) -> 0 | I17: =IF($E17<J$4,($G17*1.3)/4,0) -> 0 | J17: =IF($E17<K$4,($G17*1.3)/4,0) -> 0 | K17: =IF($E17<L$4,($G17*1.3)/4,0) -> 0 | L17: =IF($E17<M$4,($G17*1.3)/4,0) -> 0 | M17: =IF($E17<N$4,($G17*1.3)/4,0) -> 0 | N17: =IF($E17<O$4,($G17*1.3)/4,0) -> 0 | O17: =IF($E17<P$4,($G17*1.3)/4,0) -> 0 | ... R17: =IF($E17<S$4,($G17*1.3)/4,0) -> 0 | S17: =IF($E17<S$4,($G17*1.3)/4,0) -> 0
... H24: =IF($E24<I$4,($G24*1.3)/4,0) -> 0 | I24: =IF($E24<J$4,($G24*1.3)/4,0) -> 0 | J24: =IF($E24<K$4,($G24*1.3)/4,0) -> 0 | K24: =IF($E24<L$4,($G24*1.3)/4,0) -> 0 | L24: =IF($E24<M$4,($G24*1.3)/4,0) -> 0 | M24: =IF($E24<N$4,($G24*1.3)/4,0) -> 0 | N24: =IF($E24<O$4,($G24*1.3)/4,0) -> 0 | O24: =IF($E24<P$4,($G24*1.3)/4,0) -> 0 | ... R24: =IF($E24<S$4,($G24*1.3)/4,0) -> 0 | S24: =IF($E24<S$4,($G24*1.3)/4,0) -> 0
H25: =SUM(H6:H24) -> 0 | I25: =SUM(I6:I24) -> 0 | J25: =SUM(J6:J24) -> 0 | K25: =SUM(K6:K24) -> 0 | L25: =SUM(L6:L24) -> 0 | M25: =SUM(M6:M24) -> 0 | N25: =SUM(N6:N24) -> 0 | O25: =SUM(O6:O24) -> 0 | ... S25: =SUM(S6:S24) -> 0
A27: Non Headcount | H27: 2019 | J27: 2020 | N27: 2021 | R27: 2022
A28: Submitted by | B28: Department | C28: Description of Spend | D28: Justification | G28: Total Cost Estimate | H28: Q3 | I28: Q4 | J28: Q1 | K28: Q2 | L28: Q3 | M28: Q4 | N28: Q1 | O28: Q2 | P28: Q3 | Q28: Q4 | R28: Q1 | S28: Q2
A29: Peter Schaffer | B29: Delta | C29: Rent-Current premises | D29: Office Space -lease obligation through 6/31/2020 | G29: =SUM(I29:M29) -> 68889 | I29: 22963 | J29: 22963 | K29: 22963
A30: Nish,Peter&LB Email | B30: Workplace | C30: "Base" Rent for WeWork | D30: Assumes 26 heads Q1 - 28 heads Q3 - flat at 28 forward - numbers reflect cost to secure the space in Q1 | G30: =SUM(I30:O30) -> 617904 | J30: =(28*1839)*3 -> 154476 | K30: =(28*1839)*3 -> 154476 | L30: =(28*1839)*3 -> 154476 | M30: =(28*1839)*3 -> 154476
G41: =SUM(G29:G40) -> 686793 | H41: =SUM(H29:H34) -> 0 | I41: =SUM(I29:I34) -> 22963 | J41: =SUM(J29:J34) -> 177439 | K41: =SUM(K29:K34) -> 177439 | L41: =SUM(L29:L34) -> 154476 | M41: =SUM(M29:M34) -> 154476 | N41: =SUM(N29:N34) -> 0 | O41: =SUM(O29:O34) -> 0 | ... S41: =SUM(S29:S34) -> 0

Sheet 11) IT-Infrastructure
A1: Delta Incremental Costs
A3: Headcount | H3: 2019 | J3: 2020 | N3: 2021 | R3: 2022
H4: 43647 | I4: 43739 | J4: 43831 | K4: 43922 | L4: 44013 | M4: 44105 | N4: 44197 | O4: 44287 | P4: 44378 | Q4: 44470 | R4: 44562 | S4: 44652
A5: Submitted by | B5: Department | C5: TBH Title | D5: Description | E5: Hire Date | F5: Location | G5: Base Salary Estimate USD | H5: Q3 | I5: Q4 | J5: Q1 | K5: Q2 | L5: Q3 | M5: Q4 | N5: Q1 | O5: Q2 | P5: Q3 | Q5: Q4 | R5: Q1 | S5: Q2
A6: n/a - utilize existing MSP/ HC IT support strategy for region | G6: 0 | H6: =IF($E6<I$4,($G6*1.3)/4,0) -> 0 | I6: =IF($E6<J$4,($G6*1.3)/4,0) -> 0 | J6: =IF($E6<K$4,($G6*1.3)/4,0) -> 0 | K6: =IF($E6<L$4,($G6*1.3)/4,0) -> 0 | L6: =IF($E6<M$4,($G6*1.3)/4,0) -> 0 | M6: =IF($E6<N$4,($G6*1.3)/4,0) -> 0 | N6: =IF($E6<O$4,($G6*1.3)/4,0) -> 0 | O6: =IF($E6<P$4,($G6*1.3)/4,0) -> 0 | ... R6: =IF($E6<S$4,($G6*1.3)/4,0) -> 0 | S6: =IF($E6<S$4,($G6*1.3)/4,0) -> 0
H7: =IF($E7<I$4,($G7*1.3)/4,0) -> 0 | I7: =IF($E7<J$4,($G7*1.3)/4,0) -> 0 | J7: =IF($E7<K$4,($G7*1.3)/4,0) -> 0 | K7: =IF($E7<L$4,($G7*1.3)/4,0) -> 0 | L7: =IF($E7<M$4,($G7*1.3)/4,0) -> 0 | M7: =IF($E7<N$4,($G7*1.3)/4,0) -> 0 | N7: =IF($E7<O$4,($G7*1.3)/4,0) -> 0 | O7: =IF($E7<P$4,($G7*1.3)/4,0) -> 0 | ... R7: =IF($E7<S$4,($G7*1.3)/4,0) -> 0 | S7: =IF($E7<S$4,($G7*1.3)/4,0) -> 0
H8: =IF($E8<I$4,($G8*1.3)/4,0) -> 0 | I8: =IF($E8<J$4,($G8*1.3)/4,0) -> 0 | J8: =IF($E8<K$4,($G8*1.3)/4,0) -> 0 | K8: =IF($E8<L$4,($G8*1.3)/4,0) -> 0 | L8: =IF($E8<M$4,($G8*1.3)/4,0) -> 0 | M8: =IF($E8<N$4,($G8*1.3)/4,0) -> 0 | N8: =IF($E8<O$4,($G8*1.3)/4,0) -> 0 | O8: =IF($E8<P$4,($G8*1.3)/4,0) -> 0 | ... R8: =IF($E8<S$4,($G8*1.3)/4,0) -> 0 | S8: =IF($E8<S$4,($G8*1.3)/4,0) -> 0
H9: =IF($E9<I$4,($G9*1.3)/4,0) -> 0 | I9: =IF($E9<J$4,($G9*1.3)/4,0) -> 0 | J9: =IF($E9<K$4,($G9*1.3)/4,0) -> 0 | K9: =IF($E9<L$4,($G9*1.3)/4,0) -> 0 | L9: =IF($E9<M$4,($G9*1.3)/4,0) -> 0 | M9: =IF($E9<N$4,($G9*1.3)/4,0) -> 0 | N9: =IF($E9<O$4,($G9*1.3)/4,0) -> 0 | O9: =IF($E9<P$4,($G9*1.3)/4,0) -> 0 | ... R9: =IF($E9<S$4,($G9*1.3)/4,0) -> 0 | S9: =IF($E9<S$4,($G9*1.3)/4,0) -> 0
H10: =IF($E10<I$4,($G10*1.3)/4,0) -> 0 | I10: =IF($E10<J$4,($G10*1.3)/4,0) -> 0 | J10: =IF($E10<K$4,($G10*1.3)/4,0) -> 0 | K10: =IF($E10<L$4,($G10*1.3)/4,0) -> 0 | L10: =IF($E10<M$4,($G10*1.3)/4,0) -> 0 | M10: =IF($E10<N$4,($G10*1.3)/4,0) -> 0 | N10: =IF($E10<O$4,($G10*1.3)/4,0) -> 0 | O10: =IF($E10<P$4,($G10*1.3)/4,0) -> 0 | ... R10: =IF($E10<S$4,($G10*1.3)/4,0) -> 0 | S10: =IF($E10<S$4,($G10*1.3)/4,0) -> 0
H11: =IF($E11<I$4,($G11*1.3)/4,0) -> 0 | I11: =IF($E11<J$4,($G11*1.3)/4,0) -> 0 | J11: =IF($E11<K$4,($G11*1.3)/4,0) -> 0 | K11: =IF($E11<L$4,($G11*1.3)/4,0) -> 0 | L11: =IF($E11<M$4,($G11*1.3)/4,0) -> 0 | M11: =IF($E11<N$4,($G11*1.3)/4,0) -> 0 | N11: =IF($E11<O$4,($G11*1.3)/4,0) -> 0 | O11: =IF($E11<P$4,($G11*1.3)/4,0) -> 0 | ... R11: =IF($E11<S$4,($G11*1.3)/4,0) -> 0 | S11: =IF($E11<S$4,($G11*1.3)/4,0) -> 0
H12: =IF($E12<I$4,($G12*1.3)/4,0) -> 0 | I12: =IF($E12<J$4,($G12*1.3)/4,0) -> 0 | J12: =IF($E12<K$4,($G12*1.3)/4,0) -> 0 | K12: =IF($E12<L$4,($G12*1.3)/4,0) -> 0 | L12: =IF($E12<M$4,($G12*1.3)/4,0) -> 0 | M12: =IF($E12<N$4,($G12*1.3)/4,0) -> 0 | N12: =IF($E12<O$4,($G12*1.3)/4,0) -> 0 | O12: =IF($E12<P$4,($G12*1.3)/4,0) -> 0 | ... R12: =IF($E12<S$4,($G12*1.3)/4,0) -> 0 | S12: =IF($E12<S$4,($G12*1.3)/4,0) -> 0
H13: =IF($E13<I$4,($G13*1.3)/4,0) -> 0 | I13: =IF($E13<J$4,($G13*1.3)/4,0) -> 0 | J13: =IF($E13<K$4,($G13*1.3)/4,0) -> 0 | K13: =IF($E13<L$4,($G13*1.3)/4,0) -> 0 | L13: =IF($E13<M$4,($G13*1.3)/4,0) -> 0 | M13: =IF($E13<N$4,($G13*1.3)/4,0) -> 0 | N13: =IF($E13<O$4,($G13*1.3)/4,0) -> 0 | O13: =IF($E13<P$4,($G13*1.3)/4,0) -> 0 | ... R13: =IF($E13<S$4,($G13*1.3)/4,0) -> 0 | S13: =IF($E13<S$4,($G13*1.3)/4,0) -> 0
H14: =IF($E14<I$4,($G14*1.3)/4,0) -> 0 | I14: =IF($E14<J$4,($G14*1.3)/4,0) -> 0 | J14: =IF($E14<K$4,($G14*1.3)/4,0) -> 0 | K14: =IF($E14<L$4,($G14*1.3)/4,0) -> 0 | L14: =IF($E14<M$4,($G14*1.3)/4,0) -> 0 | M14: =IF($E14<N$4,($G14*1.3)/4,0) -> 0 | N14: =IF($E14<O$4,($G14*1.3)/4,0) -> 0 | O14: =IF($E14<P$4,($G14*1.3)/4,0) -> 0 | ... R14: =IF($E14<S$4,($G14*1.3)/4,0) -> 0 | S14: =IF($E14<S$4,($G14*1.3)/4,0) -> 0
H15: =IF($E15<I$4,($G15*1.3)/4,0) -> 0 | I15: =IF($E15<J$4,($G15*1.3)/4,0) -> 0 | J15: =IF($E15<K$4,($G15*1.3)/4,0) -> 0 | K15: =IF($E15<L$4,($G15*1.3)/4,0) -> 0 | L15: =IF($E15<M$4,($G15*1.3)/4,0) -> 0 | M15: =IF($E15<N$4,($G15*1.3)/4,0) -> 0 | N15: =IF($E15<O$4,($G15*1.3)/4,0) -> 0 | O15: =IF($E15<P$4,($G15*1.3)/4,0) -> 0 | ... R15: =IF($E15<S$4,($G15*1.3)/4,0) -> 0 | S15: =IF($E15<S$4,($G15*1.3)/4,0) -> 0
H16: =IF($E16<I$4,($G16*1.3)/4,0) -> 0 | I16: =IF($E16<J$4,($G16*1.3)/4,0) -> 0 | J16: =IF($E16<K$4,($G16*1.3)/4,0) -> 0 | K16: =IF($E16<L$4,($G16*1.3)/4,0) -> 0 | L16: =IF($E16<M$4,($G16*1.3)/4,0) -> 0 | M16: =IF($E16<N$4,($G16*1.3)/4,0) -> 0 | N16: =IF($E16<O$4,($G16*1.3)/4,0) -> 0 | O16: =IF($E16<P$4,($G16*1.3)/4,0) -> 0 | ... R16: =IF($E16<S$4,($G16*1.3)/4,0) -> 0 | S16: =IF($E16<S$4,($G16*1.3)/4,0) -> 0
H17: =IF($E17<I$4,($G17*1.3)/4,0) -> 0 | I17: =IF($E17<J$4,($G17*1.3)/4,0) -> 0 | J17: =IF($E17<K$4,($G17*1.3)/4,0) -> 0 | K17: =IF($E17<L$4,($G17*1.3)/4,0) -> 0 | L17: =IF($E17<M$4,($G17*1.3)/4,0) -> 0 | M17: =IF($E17<N$4,($G17*1.3)/4,0) -> 0 | N17: =IF($E17<O$4,($G17*1.3)/4,0) -> 0 | O17: =IF($E17<P$4,($G17*1.3)/4,0) -> 0 | ... R17: =IF($E17<S$4,($G17*1.3)/4,0) -> 0 | S17: =IF($E17<S$4,($G17*1.3)/4,0) -> 0
H18: =IF($E18<I$4,($G18*1.3)/4,0) -> 0 | I18: =IF($E18<J$4,($G18*1.3)/4,0) -> 0 | J18: =IF($E18<K$4,($G18*1.3)/4,0) -> 0 | K18: =IF($E18<L$4,($G18*1.3)/4,0) -> 0 | L18: =IF($E18<M$4,($G18*1.3)/4,0) -> 0 | M18: =IF($E18<N$4,($G18*1.3)/4,0) -> 0 | N18: =IF($E18<O$4,($G18*1.3)/4,0) -> 0 | O18: =IF($E18<P$4,($G18*1.3)/4,0) -> 0 | ... R18: =IF($E18<S$4,($G18*1.3)/4,0) -> 0 | S18: =IF($E18<S$4,($G18*1.3)/4,0) -> 0
... H24: =IF($E24<I$4,($G24*1.3)/4,0) -> 0 | I24: =IF($E24<J$4,($G24*1.3)/4,0) -> 0 | J24: =IF($E24<K$4,($G24*1.3)/4,0) -> 0 | K24: =IF($E24<L$4,($G24*1.3)/4,0) -> 0 | L24: =IF($E24<M$4,($G24*1.3)/4,0) -> 0 | M24: =IF($E24<N$4,($G24*1.3)/4,0) -> 0 | N24: =IF($E24<O$4,($G24*1.3)/4,0) -> 0 | O24: =IF($E24<P$4,($G24*1.3)/4,0) -> 0 | ... R24: =IF($E24<S$4,($G24*1.3)/4,0) -> 0 | S24: =IF($E24<S$4,($G24*1.3)/4,0) -> 0
H25: =SUM(H6:H24) -> 0 | I25: =SUM(I6:I24) -> 0 | J25: =SUM(J6:J24) -> 0 | K25: =SUM(K6:K24) -> 0 | L25: =SUM(L6:L24) -> 0 | M25: =SUM(M6:M24) -> 0 | N25: =SUM(N6:N24) -> 0 | O25: =SUM(O6:O24) -> 0 | ... S25: =SUM(S6:S24) -> 0
A27: Non Headcount | H27: 2019 | J27: 2020 | N27: 2021 | R27: 2022
A28: Submitted by | B28: Department | C28: Description of Spend | D28: Justification | G28: Total Cost Estimate | H28: Q3 | I28: Q4 | J28: Q1 | K28: Q2 | L28: Q3 | M28: Q4 | N28: Q1 | O28: Q2 | P28: Q3 | Q28: Q4 | R28: Q1 | S28: Q2
A29: BBragg | B29: 8010 | C29: Laptops/ Monitors / Docs | D29: Hitrust compliance and employee productivity standard, Apac expensed in Qtr | G29: =SUM(H29:M29) -> 90000 | I29: =18*5000 -> 90000
A30: BBragg | B30: 8010 | C30: Zoom Equipment | D30: Presumes conference needs at location met by facility and laptops | G30: n/a
A31: BBragg | B31: 8010 | C31: Fitbit-Corp Wifi | D31: Presumes co-working location (e.g. WeWork?) and procuring as a service from the facility. | G31: =SUM(H31:M31) -> 50000 | I31: 10000 | J31: 10000 | K31: 10000 | L31: 10000 | M31: 10000
A32: BBragg | B32: 8010 | C32: Printers | D32: Presume co-working location provided and usage billed to local CC | G32: n/a
A33: BBragg | B33: 8010 | C33: Google/ Slack /Zoom /O365 | D33: Sufficient existing terms | G33: n/a
A34: BBragg | B34: Likely Jonah Org as current model | C34: Special software : Adobe, Zepplin, Sketch | D34: Existing design tools and similar to FB standards used by ID | G34: =SUM(H34:M34) -> 20000 | I34: 10000 | M34: 10000
A35: BBragg | B35: 8010 | C35: Outside Services | D35: Temp IT Systems Engineer in APAC to support, transition and decom existing internal systems | G35: =SUM(H35:M35) -> 30000 | I35: 30000
G41: =SUM(G29:G40) -> 190000 | H41: =SUM(H29:H34) -> 0 | I41: =SUM(I29:I34) -> 110000 | J41: =SUM(J29:J34) -> 10000 | K41: =SUM(K29:K34) -> 10000 | L41: =SUM(L29:L34) -> 10000 | M41: =SUM(M29:M34) -> 20000 | N41: =SUM(N29:N34) -> 0 | O41: =SUM(O29:O34) -> 0 | ... S41: =SUM(S29:S34) -> 0

Sheet 13) IT- Security
A1: Delta Incremental Costs
A3: Headcount | H3: 2019 | J3: 2020 | N3: 2021 | R3: 2022
H4: 43647 | I4: 43739 | J4: 43831 | K4: 43922 | L4: 44013 | M4: 44105 | N4: 44197 | O4: 44287 | P4: 44378 | Q4: 44470 | R4: 44562 | S4: 44652
A5: Submitted by | B5: Department | C5: TBH Title | D5: Description | E5: Hire Date | F5: Location | G5: Base Salary Estimate USD | H5: Q3 | I5: Q4 | J5: Q1 | K5: Q2 | L5: Q3 | M5: Q4 | N5: Q1 | O5: Q2 | P5: Q3 | Q5: Q4 | R5: Q1 | S5: Q2
H6: =IF($E6<I$4,($G6*1.3)/4,0) -> 0 | I6: =IF($E6<J$4,($G6*1.3)/4,0) -> 0 | J6: =IF($E6<K$4,($G6*1.3)/4,0) -> 0 | K6: =IF($E6<L$4,($G6*1.3)/4,0) -> 0 | L6: =IF($E6<M$4,($G6*1.3)/4,0) -> 0 | M6: =IF($E6<N$4,($G6*1.3)/4,0) -> 0 | N6: =IF($E6<O$4,($G6*1.3)/4,0) -> 0 | O6: =IF($E6<P$4,($G6*1.3)/4,0) -> 0 | ... R6: =IF($E6<S$4,($G6*1.3)/4,0) -> 0 | S6: =IF($E6<S$4,($G6*1.3)/4,0) -> 0
H7: =IF($E7<I$4,($G7*1.3)/4,0) -> 0 | I7: =IF($E7<J$4,($G7*1.3)/4,0) -> 0 | J7: =IF($E7<K$4,($G7*1.3)/4,0) -> 0 | K7: =IF($E7<L$4,($G7*1.3)/4,0) -> 0 | L7: =IF($E7<M$4,($G7*1.3)/4,0) -> 0 | M7: =IF($E7<N$4,($G7*1.3)/4,0) -> 0 | N7: =IF($E7<O$4,($G7*1.3)/4,0) -> 0 | O7: =IF($E7<P$4,($G7*1.3)/4,0) -> 0 | ... R7: =IF($E7<S$4,($G7*1.3)/4,0) -> 0 | S7: =IF($E7<S$4,($G7*1.3)/4,0) -> 0
H8: =IF($E8<I$4,($G8*1.3)/4,0) -> 0 | I8: =IF($E8<J$4,($G8*1.3)/4,0) -> 0 | J8: =IF($E8<K$4,($G8*1.3)/4,0) -> 0 | K8: =IF($E8<L$4,($G8*1.3)/4,0) -> 0 | L8: =IF($E8<M$4,($G8*1.3)/4,0) -> 0 | M8: =IF($E8<N$4,($G8*1.3)/4,0) -> 0 | N8: =IF($E8<O$4,($G8*1.3)/4,0) -> 0 | O8: =IF($E8<P$4,($G8*1.3)/4,0) -> 0 | ... R8: =IF($E8<S$4,($G8*1.3)/4,0) -> 0 | S8: =IF($E8<S$4,($G8*1.3)/4,0) -> 0
H9: =IF($E9<I$4,($G9*1.3)/4,0) -> 0 | I9: =IF($E9<J$4,($G9*1.3)/4,0) -> 0 | J9: =IF($E9<K$4,($G9*1.3)/4,0) -> 0 | K9: =IF($E9<L$4,($G9*1.3)/4,0) -> 0 | L9: =IF($E9<M$4,($G9*1.3)/4,0) -> 0 | M9: =IF($E9<N$4,($G9*1.3)/4,0) -> 0 | N9: =IF($E9<O$4,($G9*1.3)/4,0) -> 0 | O9: =IF($E9<P$4,($G9*1.3)/4,0) -> 0 | ... R9: =IF($E9<S$4,($G9*1.3)/4,0) -> 0 | S9: =IF($E9<S$4,($G9*1.3)/4,0) -> 0
H10: =IF($E10<I$4,($G10*1.3)/4,0) -> 0 | I10: =IF($E10<J$4,($G10*1.3)/4,0) -> 0 | J10: =IF($E10<K$4,($G10*1.3)/4,0) -> 0 | K10: =IF($E10<L$4,($G10*1.3)/4,0) -> 0 | L10: =IF($E10<M$4,($G10*1.3)/4,0) -> 0 | M10: =IF($E10<N$4,($G10*1.3)/4,0) -> 0 | N10: =IF($E10<O$4,($G10*1.3)/4,0) -> 0 | O10: =IF($E10<P$4,($G10*1.3)/4,0) -> 0 | ... R10: =IF($E10<S$4,($G10*1.3)/4,0) -> 0 | S10: =IF($E10<S$4,($G10*1.3)/4,0) -> 0
H11: =IF($E11<I$4,($G11*1.3)/4,0) -> 0 | I11: =IF($E11<J$4,($G11*1.3)/4,0) -> 0 | J11: =IF($E11<K$4,($G11*1.3)/4,0) -> 0 | K11: =IF($E11<L$4,($G11*1.3)/4,0) -> 0 | L11: =IF($E11<M$4,($G11*1.3)/4,0) -> 0 | M11: =IF($E11<N$4,($G11*1.3)/4,0) -> 0 | N11: =IF($E11<O$4,($G11*1.3)/4,0) -> 0 | O11: =IF($E11<P$4,($G11*1.3)/4,0) -> 0 | ... R11: =IF($E11<S$4,($G11*1.3)/4,0) -> 0 | S11: =IF($E11<S$4,($G11*1.3)/4,0) -> 0
